Workbook
Name AUpdate: 1
Name BUpdate: 1
Name GUpdate: 0
Name TUpdate: 1

Sheet Revenue
A1: 個股 | B1: 名稱 | C1: 產業別 | D1: =營收表現!C$3 -> 202508單月合併營收月變動(%) | E1: =營收表現!D$3 -> 202509單月合併營收月變動(%) | F1: =營收表現!E$3 -> 202510單月合併營收月變動(%) | G1: =營收表現!F$3 -> 202511單月合併營收月變動(%) | H1: =營收表現!G$3 -> 202512單月合併營收月變動(%) | I1: =營收表現!H$3 -> 202601單月合併營收月變動(%) | J1: =營收表現!I$3 -> 202508單月合併營收年成長(%) | K1: =營收表現!J$3 -> 202509單月合併營收年成長(%) | ... O1: =營收表現!N$3 -> 202601單月合併營收年成長(%)
A2: 2330 | B2: =IFERROR(INDEX(營收表現!B$6:B$3000,MATCH($A2,營收表現!$A$6:$A$3000,0)),"") -> 台積電 | C2: =IFERROR(INDEX(類別!G$4:G$3000,MATCH($A2,類別!$C$4:$C$3000,0)),"") -> IC代工 | D2: =IFERROR(IF(INDEX(營收表現!C$6:C$3000,MATCH($A2,營收表現!$A$6:$A$3000,0))="","",INDEX(營收表現!C$6:C$3000,MATCH($A2,營收表現!$A$6:$A$3000,0))),"") -> 3.9 | E2: =IFERROR(IF(INDEX(營收表現!D$6:D$3000,MATCH($A2,營收表現!$A$6:$A$3000,0))="","",INDEX(營收表現!D$6:D$3000,MATCH($A2,營收表現!$A$6:$A$3000,0))),"") -> -1.43 | F2: =IFERROR(IF(INDEX(營收表現!E$6:E$3000,MATCH($A2,營收表現!$A$6:$A$3000,0))="","",INDEX(營收表現!E$6:E$3000,MATCH($A2,營收表現!$A$6:$A$3000,0))),"") -> 11.03 | G2: =IFERROR(IF(INDEX(營收表現!F$6:F$3000,MATCH($A2,營收表現!$A$6:$A$3000,0))="","",INDEX(營收表現!F$6:F$3000,MATCH($A2,營收表現!$A$6:$A$3000,0))),"") -> -6.49 | H2: =IFERROR(IF(INDEX(營收表現!G$6:G$3000,MATCH($A2,營收表現!$A$6:$A$3000,0))="","",INDEX(營收表現!G$6:G$3000,MATCH($A2,營收表現!$A$6:$A$3000,0))),"") -> -2.51 | I2: =IFERROR(IF(INDEX(營收表現!H$6:H$3000,MATCH($A2,營收表現!$A$6:$A$3000,0))="","",INDEX(營收表現!H$6:H$3000,MATCH($A2,營收表現!$A$6:$A$3000,0))),"") -> 19.78 | J2: =IFERROR(IF(INDEX(營收表現!I$6:I$3000,MATCH($A2,營收表現!$A$6:$A$3000,0))="","",INDEX(營收表現!I$6:I$3000,MATCH($A2,營收表現!$A$6:$A$3000,0))),"") -> 33.84 | K2: =IFERROR(IF(INDEX(營收表現!J$6:J$3000,MATCH($A2,營收表現!$A$6:$A$3000,0))="","",INDEX(營收表現!J$6:J$3000,MATCH($A2,營收表現!$A$6:$A$3000,0))),"") -> 31.41 | ... N2: =IFERROR(IF(INDEX(營收表現!M$6:M$3000,MATCH($A2,營收表現!$A$6:$A$3000,0))="","",INDEX(營收表現!M$6:M$3000,MATCH($A2,營收表現!$A$6:$A$3000,0))),"") -> 20.43 | O2: =IF(INDEX(營收表現!N$6:N$3000,MATCH($A2,營收表現!$A$6:$A$3000,0))="","",INDEX(營收表現!N$6:N$3000,MATCH($A2,營收表現!$A$6:$A$3000,0))) -> 36.81
A3: 2454 | B3: =IFERROR(INDEX(營收表現!B$6:B$3000,MATCH($A3,營收表現!$A$6:$A$3000,0)),"") -> 聯發科 | C3: =IFERROR(INDEX(類別!G$4:G$3000,MATCH($A3,類別!$C$4:$C$3000,0)),"") -> 網通IC | D3: =IFERROR(IF(INDEX(營收表現!C$6:C$3000,MATCH($A3,營收表現!$A$6:$A$3000,0))="","",INDEX(營收表現!C$6:C$3000,MATCH($A3,營收表現!$A$6:$A$3000,0))),"") -> 3.07 | E3: =IFERROR(IF(INDEX(營收表現!D$6:D$3000,MATCH($A3,營收表現!$A$6:$A$3000,0))="","",INDEX(營收表現!D$6:D$3000,MATCH($A3,營收表現!$A$6:$A$3000,0))),"") -> 21.96 | F3: =IFERROR(IF(INDEX(營收表現!E$6:E$3000,MATCH($A3,營收表現!$A$6:$A$3000,0))="","",INDEX(營收表現!E$6:E$3000,MATCH($A3,營收表現!$A$6:$A$3000,0))),"") -> -4.24 | G3: =IFERROR(IF(INDEX(營收表現!F$6:F$3000,MATCH($A3,營收表現!$A$6:$A$3000,0))="","",INDEX(營收表現!F$6:F$3000,MATCH($A3,營收表現!$A$6:$A$3000,0))),"") -> -9.86 | H3: =IFERROR(IF(INDEX(營收表現!G$6:G$3000,MATCH($A3,營收表現!$A$6:$A$3000,0))="","",INDEX(營收表現!G$6:G$3000,MATCH($A3,營收表現!$A$6:$A$3000,0))),"") -> 9.32 | I3: =IFERROR(IF(INDEX(營收表現!H$6:H$3000,MATCH($A3,營收表現!$A$6:$A$3000,0))="","",INDEX(營收表現!H$6:H$3000,MATCH($A3,營收表現!$A$6:$A$3000,0))),"") | J3: =IFERROR(IF(INDEX(營收表現!I$6:I$3000,MATCH($A3,營收表現!$A$6:$A$3000,0))="","",INDEX(營收表現!I$6:I$3000,MATCH($A3,營收表現!$A$6:$A$3000,0))),"") -> 7.27 | K3: =IFERROR(IF(INDEX(營收表現!J$6:J$3000,MATCH($A3,營收表現!$A$6:$A$3000,0))="","",INDEX(營收表現!J$6:J$3000,MATCH($A3,營收表現!$A$6:$A$3000,0))),"") -> 21.61 | ... N3: =IFERROR(IF(INDEX(營收表現!M$6:M$3000,MATCH($A3,營收表現!$A$6:$A$3000,0))="","",INDEX(營收表現!M$6:M$3000,MATCH($A3,營收表現!$A$6:$A$3000,0))),"") -> 22.99 | O3: =IF(INDEX(營收表現!N$6:N$3000,MATCH($A3,營收表現!$A$6:$A$3000,0))="","",INDEX(營收表現!N$6:N$3000,MATCH($A3,營收表現!$A$6:$A$3000,0)))
A4: 2338 | B4: =IFERROR(INDEX(營收表現!B$6:B$3000,MATCH($A4,營收表現!$A$6:$A$3000,0)),"") -> 光罩 | C4: =IFERROR(INDEX(類別!G$4:G$3000,MATCH($A4,類別!$C$4:$C$3000,0)),"") -> 半導體設備 | D4: =IFERROR(IF(INDEX(營收表現!C$6:C$3000,MATCH($A4,營收表現!$A$6:$A$3000,0))="","",INDEX(營收表現!C$6:C$3000,MATCH($A4,營收表現!$A$6:$A$3000,0))),"") -> 12.2 | E4: =IFERROR(IF(INDEX(營收表現!D$6:D$3000,MATCH($A4,營收表現!$A$6:$A$3000,0))="","",INDEX(營收表現!D$6:D$3000,MATCH($A4,營收表現!$A$6:$A$3000,0))),"") -> -22.02 | F4: =IFERROR(IF(INDEX(營收表現!E$6:E$3000,MATCH($A4,營收表現!$A$6:$A$3000,0))="","",INDEX(營收表現!E$6:E$3000,MATCH($A4,營收表現!$A$6:$A$3000,0))),"") -> 2.37 | G4: =IFERROR(IF(INDEX(營收表現!F$6:F$3000,MATCH($A4,營收表現!$A$6:$A$3000,0))="","",INDEX(營收表現!F$6:F$3000,MATCH($A4,營收表現!$A$6:$A$3000,0))),"") -> 5.87 | H4: =IFERROR(IF(INDEX(營收表現!G$6:G$3000,MATCH($A4,營收表現!$A$6:$A$3000,0))="","",INDEX(營收表現!G$6:G$3000,MATCH($A4,營收表現!$A$6:$A$3000,0))),"") -> 4.05 | I4: =IFERROR(IF(INDEX(營收表現!H$6:H$3000,MATCH($A4,營收表現!$A$6:$A$3000,0))="","",INDEX(營收表現!H$6:H$3000,MATCH($A4,營收表現!$A$6:$A$3000,0))),"") -> 12.4 | J4: =IFERROR(IF(INDEX(營收表現!I$6:I$3000,MATCH($A4,營收表現!$A$6:$A$3000,0))="","",INDEX(營收表現!I$6:I$3000,MATCH($A4,營收表現!$A$6:$A$3000,0))),"") -> -2.64 | K4: =IFERROR(IF(INDEX(營收表現!J$6:J$3000,MATCH($A4,營收表現!$A$6:$A$3000,0))="","",INDEX(營收表現!J$6:J$3000,MATCH($A4,營收表現!$A$6:$A$3000,0))),"") -> -33.69 | ... N4: =IFERROR(IF(INDEX(營收表現!M$6:M$3000,MATCH($A4,營收表現!$A$6:$A$3000,0))="","",INDEX(營收表現!M$6:M$3000,MATCH($A4,營收表現!$A$6:$A$3000,0))),"") -> -26.79 | O4: =IF(INDEX(營收表現!N$6:N$3000,MATCH($A4,營收表現!$A$6:$A$3000,0))="","",INDEX(營收表現!N$6:N$3000,MATCH($A4,營收表現!$A$6:$A$3000,0))) -> -1.57
A5: 2449 | B5: =IFERROR(INDEX(營收表現!B$6:B$3000,MATCH($A5,營收表現!$A$6:$A$3000,0)),"") -> 京元電子 | C5: =IFERROR(INDEX(類別!G$4:G$3000,MATCH($A5,類別!$C$4:$C$3000,0)),"") -> IC封測 | D5: =IFERROR(IF(INDEX(營收表現!C$6:C$3000,MATCH($A5,營收表現!$A$6:$A$3000,0))="","",INDEX(營收表現!C$6:C$3000,MATCH($A5,營收表現!$A$6:$A$3000,0))),"") -> 6.26 | E5: =IFERROR(IF(INDEX(營收表現!D$6:D$3000,MATCH($A5,營收表現!$A$6:$A$3000,0))="","",INDEX(營收表現!D$6:D$3000,MATCH($A5,營收表現!$A$6:$A$3000,0))),"") -> 5.5 | F5: =IFERROR(IF(INDEX(營收表現!E$6:E$3000,MATCH($A5,營收表現!$A$6:$A$3000,0))="","",INDEX(營收表現!E$6:E$3000,MATCH($A5,營收表現!$A$6:$A$3000,0))),"") -> 4.51 | G5: =IFERROR(IF(INDEX(營收表現!F$6:F$3000,MATCH($A5,營收表現!$A$6:$A$3000,0))="","",INDEX(營收表現!F$6:F$3000,MATCH($A5,營收表現!$A$6:$A$3000,0))),"") -> -3.69 | H5: =IFERROR(IF(INDEX(營收表現!G$6:G$3000,MATCH($A5,營收表現!$A$6:$A$3000,0))="","",INDEX(營收表現!G$6:G$3000,MATCH($A5,營收表現!$A$6:$A$3000,0))),"") -> -1.16 | I5: =IFERROR(IF(INDEX(營收表現!H$6:H$3000,MATCH($A5,營收表現!$A$6:$A$3000,0))="","",INDEX(營收表現!H$6:H$3000,MATCH($A5,營收表現!$A$6:$A$3000,0))),"") -> 3.54 | J5: =IFERROR(IF(INDEX(營收表現!I$6:I$3000,MATCH($A5,營收表現!$A$6:$A$3000,0))="","",INDEX(營收表現!I$6:I$3000,MATCH($A5,營收表現!$A$6:$A$3000,0))),"") -> 31.89 | K5: =IFERROR(IF(INDEX(營收表現!J$6:J$3000,MATCH($A5,營收表現!$A$6:$A$3000,0))="","",INDEX(營收表現!J$6:J$3000,MATCH($A5,營收表現!$A$6:$A$3000,0))),"") -> 39.62 | ... N5: =IFERROR(IF(INDEX(營收表現!M$6:M$3000,MATCH($A5,營收表現!$A$6:$A$3000,0))="","",INDEX(營收表現!M$6:M$3000,MATCH($A5,營收表現!$A$6:$A$3000,0))),"") -> 33.04 | O5: =IF(INDEX(營收表現!N$6:N$3000,MATCH($A5,營收表現!$A$6:$A$3000,0))="","",INDEX(營收表現!N$6:N$3000,MATCH($A5,營收表現!$A$6:$A$3000,0))) -> 41.28
A6: 3680 | B6: =IFERROR(INDEX(營收表現!B$6:B$3000,MATCH($A6,營收表現!$A$6:$A$3000,0)),"") -> 家登 | C6: =IFERROR(INDEX(類別!G$4:G$3000,MATCH($A6,類別!$C$4:$C$3000,0)),"") -> 半導體設備 | D6: =IFERROR(IF(INDEX(營收表現!C$6:C$3000,MATCH($A6,營收表現!$A$6:$A$3000,0))="","",INDEX(營收表現!C$6:C$3000,MATCH($A6,營收表現!$A$6:$A$3000,0))),"") -> 10.4 | E6: =IFERROR(IF(INDEX(營收表現!D$6:D$3000,MATCH($A6,營收表現!$A$6:$A$3000,0))="","",INDEX(營收表現!D$6:D$3000,MATCH($A6,營收表現!$A$6:$A$3000,0))),"") -> 5.85 | F6: =IFERROR(IF(INDEX(營收表現!E$6:E$3000,MATCH($A6,營收表現!$A$6:$A$3000,0))="","",INDEX(營收表現!E$6:E$3000,MATCH($A6,營收表現!$A$6:$A$3000,0))),"") -> 11.11 | G6: =IFERROR(IF(INDEX(營收表現!F$6:F$3000,MATCH($A6,營收表現!$A$6:$A$3000,0))="","",INDEX(營收表現!F$6:F$3000,MATCH($A6,營收表現!$A$6:$A$3000,0))),"") -> 11.35 | H6: =IFERROR(IF(INDEX(營收表現!G$6:G$3000,MATCH($A6,營收表現!$A$6:$A$3000,0))="","",INDEX(營收表現!G$6:G$3000,MATCH($A6,營收表現!$A$6:$A$3000,0))),"") -> 19.07 | I6: =IFERROR(IF(INDEX(營收表現!H$6:H$3000,MATCH($A6,營收表現!$A$6:$A$3000,0))="","",INDEX(營收表現!H$6:H$3000,MATCH($A6,營收表現!$A$6:$A$3000,0))),"") -> -27.41 | J6: =IFERROR(IF(INDEX(營收表現!I$6:I$3000,MATCH($A6,營收表現!$A$6:$A$3000,0))="","",INDEX(營收表現!I$6:I$3000,MATCH($A6,營收表現!$A$6:$A$3000,0))),"") -> -13.3 | K6: =IFERROR(IF(INDEX(營收表現!J$6:J$3000,MATCH($A6,營收表現!$A$6:$A$3000,0))="","",INDEX(營收表現!J$6:J$3000,MATCH($A6,營收表現!$A$6:$A$3000,0))),"") -> -2.32 | ... N6: =IFERROR(IF(INDEX(營收表現!M$6:M$3000,MATCH($A6,營收表現!$A$6:$A$3000,0))="","",INDEX(營收表現!M$6:M$3000,MATCH($A6,營收表現!$A$6:$A$3000,0))),"") -> 49.17 | O6: =IF(INDEX(營收表現!N$6:N$3000,MATCH($A6,營收表現!$A$6:$A$3000,0))="","",INDEX(營收表現!N$6:N$3000,MATCH($A6,營收表現!$A$6:$A$3000,0))) -> 62.74
A7: 2308 | B7: =IFERROR(INDEX(營收表現!B$6:B$3000,MATCH($A7,營收表現!$A$6:$A$3000,0)),"") -> 台達電 | C7: =IFERROR(INDEX(類別!G$4:G$3000,MATCH($A7,類別!$C$4:$C$3000,0)),"") -> 供電與變壓 | D7: =IFERROR(IF(INDEX(營收表現!C$6:C$3000,MATCH($A7,營收表現!$A$6:$A$3000,0))="","",INDEX(營收表現!C$6:C$3000,MATCH($A7,營收表現!$A$6:$A$3000,0))),"") -> 5.42 | E7: =IFERROR(IF(INDEX(營收表現!D$6:D$3000,MATCH($A7,營收表現!$A$6:$A$3000,0))="","",INDEX(營收表現!D$6:D$3000,MATCH($A7,營收表現!$A$6:$A$3000,0))),"") -> 19.22 | F7: =IFERROR(IF(INDEX(營收表現!E$6:E$3000,MATCH($A7,營收表現!$A$6:$A$3000,0))="","",INDEX(營收表現!E$6:E$3000,MATCH($A7,營收表現!$A$6:$A$3000,0))),"") -> 0.57 | G7: =IFERROR(IF(INDEX(營收表現!F$6:F$3000,MATCH($A7,營收表現!$A$6:$A$3000,0))="","",INDEX(營收表現!F$6:F$3000,MATCH($A7,營收表現!$A$6:$A$3000,0))),"") -> -11.92 | H7: =IFERROR(IF(INDEX(營收表現!G$6:G$3000,MATCH($A7,營收表現!$A$6:$A$3000,0))="","",INDEX(營收表現!G$6:G$3000,MATCH($A7,營收表現!$A$6:$A$3000,0))),"") -> 6.22 | I7: =IFERROR(IF(INDEX(營收表現!H$6:H$3000,MATCH($A7,營收表現!$A$6:$A$3000,0))="","",INDEX(營收表現!H$6:H$3000,MATCH($A7,營收表現!$A$6:$A$3000,0))),"") -> -7.47 | J7: =IFERROR(IF(INDEX(營收表現!I$6:I$3000,MATCH($A7,營收表現!$A$6:$A$3000,0))="","",INDEX(營收表現!I$6:I$3000,MATCH($A7,營收表現!$A$6:$A$3000,0))),"") -> 26.71 | K7: =IFERROR(IF(INDEX(營收表現!J$6:J$3000,MATCH($A7,營收表現!$A$6:$A$3000,0))="","",INDEX(營收表現!J$6:J$3000,MATCH($A7,營收表現!$A$6:$A$3000,0))),"") -> 53.83 | ... N7: =IFERROR(IF(INDEX(營收表現!M$6:M$3000,MATCH($A7,營收表現!$A$6:$A$3000,0))="","",INDEX(營收表現!M$6:M$3000,MATCH($A7,營收表現!$A$6:$A$3000,0))),"") -> 38.59 | O7: =IF(INDEX(營收表現!N$6:N$3000,MATCH($A7,營收表現!$A$6:$A$3000,0))="","",INDEX(營收表現!N$6:N$3000,MATCH($A7,營收表現!$A$6:$A$3000,0))) -> 32.87
A8: 3711 | B8: =IFERROR(INDEX(營收表現!B$6:B$3000,MATCH($A8,營收表現!$A$6:$A$3000,0)),"") -> 日月光投控 | C8: =IFERROR(INDEX(類別!G$4:G$3000,MATCH($A8,類別!$C$4:$C$3000,0)),"") -> IC封測 | D8: =IFERROR(IF(INDEX(營收表現!C$6:C$3000,MATCH($A8,營收表現!$A$6:$A$3000,0))="","",INDEX(營收表現!C$6:C$3000,MATCH($A8,營收表現!$A$6:$A$3000,0))),"") -> 9.55 | E8: =IFERROR(IF(INDEX(營收表現!D$6:D$3000,MATCH($A8,營收表現!$A$6:$A$3000,0))="","",INDEX(營收表現!D$6:D$3000,MATCH($A8,營收表現!$A$6:$A$3000,0))),"") -> 7.25 | F8: =IFERROR(IF(INDEX(營收表現!E$6:E$3000,MATCH($A8,營收表現!$A$6:$A$3000,0))="","",INDEX(營收表現!E$6:E$3000,MATCH($A8,營收表現!$A$6:$A$3000,0))),"") -> -0.55 | G8: =IFERROR(IF(INDEX(營收表現!F$6:F$3000,MATCH($A8,營收表現!$A$6:$A$3000,0))="","",INDEX(營收表現!F$6:F$3000,MATCH($A8,營收表現!$A$6:$A$3000,0))),"") -> -2.34 | H8: =IFERROR(IF(INDEX(營收表現!G$6:G$3000,MATCH($A8,營收表現!$A$6:$A$3000,0))="","",INDEX(營收表現!G$6:G$3000,MATCH($A8,營收表現!$A$6:$A$3000,0))),"") -> 0.08 | I8: =IFERROR(IF(INDEX(營收表現!H$6:H$3000,MATCH($A8,營收表現!$A$6:$A$3000,0))="","",INDEX(營收表現!H$6:H$3000,MATCH($A8,營收表現!$A$6:$A$3000,0))),"") | J8: =IFERROR(IF(INDEX(營收表現!I$6:I$3000,MATCH($A8,營收表現!$A$6:$A$3000,0))="","",INDEX(營收表現!I$6:I$3000,MATCH($A8,營收表現!$A$6:$A$3000,0))),"") -> 6.68 | K8: =IFERROR(IF(INDEX(營收表現!J$6:J$3000,MATCH($A8,營收表現!$A$6:$A$3000,0))="","",INDEX(營收表現!J$6:J$3000,MATCH($A8,營收表現!$A$6:$A$3000,0))),"") -> 8.96 | ... N8: =IFERROR(IF(INDEX(營收表現!M$6:M$3000,MATCH($A8,營收表現!$A$6:$A$3000,0))="","",INDEX(營收表現!M$6:M$3000,MATCH($A8,營收表現!$A$6:$A$3000,0))),"") -> 11.27 | O8: =IF(INDEX(營收表現!N$6:N$3000,MATCH($A8,營收表現!$A$6:$A$3000,0))="","",INDEX(營收表現!N$6:N$3000,MATCH($A8,營收表現!$A$6:$A$3000,0)))
A9: 1711 | B9: =IFERROR(INDEX(營收表現!B$6:B$3000,MATCH($A9,營收表現!$A$6:$A$3000,0)),"") -> 永光 | C9: =IFERROR(INDEX(類別!G$4:G$3000,MATCH($A9,類別!$C$4:$C$3000,0)),"") -> 化工 | D9: =IFERROR(IF(INDEX(營收表現!C$6:C$3000,MATCH($A9,營收表現!$A$6:$A$3000,0))="","",INDEX(營收表現!C$6:C$3000,MATCH($A9,營收表現!$A$6:$A$3000,0))),"") -> -9.75 | E9: =IFERROR(IF(INDEX(營收表現!D$6:D$3000,MATCH($A9,營收表現!$A$6:$A$3000,0))="","",INDEX(營收表現!D$6:D$3000,MATCH($A9,營收表現!$A$6:$A$3000,0))),"") -> 11.09 | F9: =IFERROR(IF(INDEX(營收表現!E$6:E$3000,MATCH($A9,營收表現!$A$6:$A$3000,0))="","",INDEX(營收表現!E$6:E$3000,MATCH($A9,營收表現!$A$6:$A$3000,0))),"") -> -6.27 | G9: =IFERROR(IF(INDEX(營收表現!F$6:F$3000,MATCH($A9,營收表現!$A$6:$A$3000,0))="","",INDEX(營收表現!F$6:F$3000,MATCH($A9,營收表現!$A$6:$A$3000,0))),"") -> 1.06 | H9: =IFERROR(IF(INDEX(營收表現!G$6:G$3000,MATCH($A9,營收表現!$A$6:$A$3000,0))="","",INDEX(營收表現!G$6:G$3000,MATCH($A9,營收表現!$A$6:$A$3000,0))),"") -> 11.85 | I9: =IFERROR(IF(INDEX(營收表現!H$6:H$3000,MATCH($A9,營收表現!$A$6:$A$3000,0))="","",INDEX(營收表現!H$6:H$3000,MATCH($A9,營收表現!$A$6:$A$3000,0))),"") -> 9.7 | J9: =IFERROR(IF(INDEX(營收表現!I$6:I$3000,MATCH($A9,營收表現!$A$6:$A$3000,0))="","",INDEX(營收表現!I$6:I$3000,MATCH($A9,營收表現!$A$6:$A$3000,0))),"") -> -15.84 | K9: =IFERROR(IF(INDEX(營收表現!J$6:J$3000,MATCH($A9,營收表現!$A$6:$A$3000,0))="","",INDEX(營收表現!J$6:J$3000,MATCH($A9,營收表現!$A$6:$A$3000,0))),"") -> -7.71 | ... N9: =IFERROR(IF(INDEX(營收表現!M$6:M$3000,MATCH($A9,營收表現!$A$6:$A$3000,0))="","",INDEX(營收表現!M$6:M$3000,MATCH($A9,營收表現!$A$6:$A$3000,0))),"") -> -8.91 | O9: =IF(INDEX(營收表現!N$6:N$3000,MATCH($A9,營收表現!$A$6:$A$3000,0))="","",INDEX(營收表現!N$6:N$3000,MATCH($A9,營收表現!$A$6:$A$3000,0))) -> 12.74
A10: 1727 | B10: =IFERROR(INDEX(營收表現!B$6:B$3000,MATCH($A10,營收表現!$A$6:$A$3000,0)),"") -> 中華化 | C10: =IFERROR(INDEX(類別!G$4:G$3000,MATCH($A10,類別!$C$4:$C$3000,0)),"") -> 化工 | D10: =IFERROR(IF(INDEX(營收表現!C$6:C$3000,MATCH($A10,營收表現!$A$6:$A$3000,0))="","",INDEX(營收表現!C$6:C$3000,MATCH($A10,營收表現!$A$6:$A$3000,0))),"") -> -11.17 | E10: =IFERROR(IF(INDEX(營收表現!D$6:D$3000,MATCH($A10,營收表現!$A$6:$A$3000,0))="","",INDEX(營收表現!D$6:D$3000,MATCH($A10,營收表現!$A$6:$A$3000,0))),"") -> 14.12 | F10: =IFERROR(IF(INDEX(營收表現!E$6:E$3000,MATCH($A10,營收表現!$A$6:$A$3000,0))="","",INDEX(營收表現!E$6:E$3000,MATCH($A10,營收表現!$A$6:$A$3000,0))),"") -> -15.84 | G10: =IFERROR(IF(INDEX(營收表現!F$6:F$3000,MATCH($A10,營收表現!$A$6:$A$3000,0))="","",INDEX(營收表現!F$6:F$3000,MATCH($A10,營收表現!$A$6:$A$3000,0))),"") -> 14.21 | H10: =IFERROR(IF(INDEX(營收表現!G$6:G$3000,MATCH($A10,營收表現!$A$6:$A$3000,0))="","",INDEX(營收表現!G$6:G$3000,MATCH($A10,營收表現!$A$6:$A$3000,0))),"") -> -7.85 | I10: =IFERROR(IF(INDEX(營收表現!H$6:H$3000,MATCH($A10,營收表現!$A$6:$A$3000,0))="","",INDEX(營收表現!H$6:H$3000,MATCH($A10,營收表現!$A$6:$A$3000,0))),"") -> -25.5 | J10: =IFERROR(IF(INDEX(營收表現!I$6:I$3000,MATCH($A10,營收表現!$A$6:$A$3000,0))="","",INDEX(營收表現!I$6:I$3000,MATCH($A10,營收表現!$A$6:$A$3000,0))),"") -> -27.8 | K10: =IFERROR(IF(INDEX(營收表現!J$6:J$3000,MATCH($A10,營收表現!$A$6:$A$3000,0))="","",INDEX(營收表現!J$6:J$3000,MATCH($A10,營收表現!$A$6:$A$3000,0))),"") -> -10.9 | ... N10: =IFERROR(IF(INDEX(營收表現!M$6:M$3000,MATCH($A10,營收表現!$A$6:$A$3000,0))="","",INDEX(營收表現!M$6:M$3000,MATCH($A10,營收表現!$A$6:$A$3000,0))),"") -> 25.08 | O10: =IF(INDEX(營收表現!N$6:N$3000,MATCH($A10,營收表現!$A$6:$A$3000,0))="","",INDEX(營收表現!N$6:N$3000,MATCH($A10,營收表現!$A$6:$A$3000,0))) -> -9.74
A11: 1717 | B11: =IFERROR(INDEX(營收表現!B$6:B$3000,MATCH($A11,營收表現!$A$6:$A$3000,0)),"") -> 長興 | C11: =IFERROR(INDEX(類別!G$4:G$3000,MATCH($A11,類別!$C$4:$C$3000,0)),"") -> 化工 | D11: =IFERROR(IF(INDEX(營收表現!C$6:C$3000,MATCH($A11,營收表現!$A$6:$A$3000,0))="","",INDEX(營收表現!C$6:C$3000,MATCH($A11,營收表現!$A$6:$A$3000,0))),"") -> 1.83 | E11: =IFERROR(IF(INDEX(營收表現!D$6:D$3000,MATCH($A11,營收表現!$A$6:$A$3000,0))="","",INDEX(營收表現!D$6:D$3000,MATCH($A11,營收表現!$A$6:$A$3000,0))),"") -> 1.85 | F11: =IFERROR(IF(INDEX(營收表現!E$6:E$3000,MATCH($A11,營收表現!$A$6:$A$3000,0))="","",INDEX(營收表現!E$6:E$3000,MATCH($A11,營收表現!$A$6:$A$3000,0))),"") -> -9.48 | G11: =IFERROR(IF(INDEX(營收表現!F$6:F$3000,MATCH($A11,營收表現!$A$6:$A$3000,0))="","",INDEX(營收表現!F$6:F$3000,MATCH($A11,營收表現!$A$6:$A$3000,0))),"") -> 6.29 | H11: =IFERROR(IF(INDEX(營收表現!G$6:G$3000,MATCH($A11,營收表現!$A$6:$A$3000,0))="","",INDEX(營收表現!G$6:G$3000,MATCH($A11,營收表現!$A$6:$A$3000,0))),"") -> 12.93 | I11: =IFERROR(IF(INDEX(營收表現!H$6:H$3000,MATCH($A11,營收表現!$A$6:$A$3000,0))="","",INDEX(營收表現!H$6:H$3000,MATCH($A11,營收表現!$A$6:$A$3000,0))),"") -> 4.45 | J11: =IFERROR(IF(INDEX(營收表現!I$6:I$3000,MATCH($A11,營收表現!$A$6:$A$3000,0))="","",INDEX(營收表現!I$6:I$3000,MATCH($A11,營收表現!$A$6:$A$3000,0))),"") -> -15.01 | K11: =IFERROR(IF(INDEX(營收表現!J$6:J$3000,MATCH($A11,營收表現!$A$6:$A$3000,0))="","",INDEX(營收表現!J$6:J$3000,MATCH($A11,營收表現!$A$6:$A$3000,0))),"") -> -5.28 | ... N11: =IFERROR(IF(INDEX(營收表現!M$6:M$3000,MATCH($A11,營收表現!$A$6:$A$3000,0))="","",INDEX(營收表現!M$6:M$3000,MATCH($A11,營收表現!$A$6:$A$3000,0))),"") -> -6.17 | O11: =IF(INDEX(營收表現!N$6:N$3000,MATCH($A11,營收表現!$A$6:$A$3000,0))="","",INDEX(營收表現!N$6:N$3000,MATCH($A11,營收表現!$A$6:$A$3000,0))) -> 16.98
A12: 6239 | B12: =IFERROR(INDEX(營收表現!B$6:B$3000,MATCH($A12,營收表現!$A$6:$A$3000,0)),"") -> 力成 | C12: =IFERROR(INDEX(類別!G$4:G$3000,MATCH($A12,類別!$C$4:$C$3000,0)),"") -> IC封測 | D12: =IFERROR(IF(INDEX(營收表現!C$6:C$3000,MATCH($A12,營收表現!$A$6:$A$3000,0))="","",INDEX(營收表現!C$6:C$3000,MATCH($A12,營收表現!$A$6:$A$3000,0))),"") -> 7.56 | E12: =IFERROR(IF(INDEX(營收表現!D$6:D$3000,MATCH($A12,營收表現!$A$6:$A$3000,0))="","",INDEX(營收表現!D$6:D$3000,MATCH($A12,營收表現!$A$6:$A$3000,0))),"") -> -2.56 | F12: =IFERROR(IF(INDEX(營收表現!E$6:E$3000,MATCH($A12,營收表現!$A$6:$A$3000,0))="","",INDEX(營收表現!E$6:E$3000,MATCH($A12,營收表現!$A$6:$A$3000,0))),"") -> 4.04 | G12: =IFERROR(IF(INDEX(營收表現!F$6:F$3000,MATCH($A12,營收表現!$A$6:$A$3000,0))="","",INDEX(營收表現!F$6:F$3000,MATCH($A12,營收表現!$A$6:$A$3000,0))),"") -> 2.43 | H12: =IFERROR(IF(INDEX(營收表現!G$6:G$3000,MATCH($A12,營收表現!$A$6:$A$3000,0))="","",INDEX(營收表現!G$6:G$3000,MATCH($A12,營收表現!$A$6:$A$3000,0))),"") -> 2.19 | I12: =IFERROR(IF(INDEX(營收表現!H$6:H$3000,MATCH($A12,營收表現!$A$6:$A$3000,0))="","",INDEX(營收表現!H$6:H$3000,MATCH($A12,營收表現!$A$6:$A$3000,0))),"") -> -0.74 | J12: =IFERROR(IF(INDEX(營收表現!I$6:I$3000,MATCH($A12,營收表現!$A$6:$A$3000,0))="","",INDEX(營收表現!I$6:I$3000,MATCH($A12,營收表現!$A$6:$A$3000,0))),"") -> 8.68 | K12: =IFERROR(IF(INDEX(營收表現!J$6:J$3000,MATCH($A12,營收表現!$A$6:$A$3000,0))="","",INDEX(營收表現!J$6:J$3000,MATCH($A12,營收表現!$A$6:$A$3000,0))),"") -> 17.42 | ... N12: =IFERROR(IF(INDEX(營收表現!M$6:M$3000,MATCH($A12,營收表現!$A$6:$A$3000,0))="","",INDEX(營收表現!M$6:M$3000,MATCH($A12,營收表現!$A$6:$A$3000,0))),"") -> 30.52 | O12: =IF(INDEX(營收表現!N$6:N$3000,MATCH($A12,營收表現!$A$6:$A$3000,0))="","",INDEX(營收表現!N$6:N$3000,MATCH($A12,營收表現!$A$6:$A$3000,0))) -> 43.04
A13: 9933 | B13: =IFERROR(INDEX(營收表現!B$6:B$3000,MATCH($A13,營收表現!$A$6:$A$3000,0)),"") -> 中鼎 | C13: =IFERROR(INDEX(類別!G$4:G$3000,MATCH($A13,類別!$C$4:$C$3000,0)),"") -> 公共工程 | D13: =IFERROR(IF(INDEX(營收表現!C$6:C$3000,MATCH($A13,營收表現!$A$6:$A$3000,0))="","",INDEX(營收表現!C$6:C$3000,MATCH($A13,營收表現!$A$6:$A$3000,0))),"") -> 1.51 | E13: =IFERROR(IF(INDEX(營收表現!D$6:D$3000,MATCH($A13,營收表現!$A$6:$A$3000,0))="","",INDEX(營收表現!D$6:D$3000,MATCH($A13,營收表現!$A$6:$A$3000,0))),"") -> 20.59 | F13: =IFERROR(IF(INDEX(營收表現!E$6:E$3000,MATCH($A13,營收表現!$A$6:$A$3000,0))="","",INDEX(營收表現!E$6:E$3000,MATCH($A13,營收表現!$A$6:$A$3000,0))),"") -> -26.84 | G13: =IFERROR(IF(INDEX(營收表現!F$6:F$3000,MATCH($A13,營收表現!$A$6:$A$3000,0))="","",INDEX(營收表現!F$6:F$3000,MATCH($A13,營收表現!$A$6:$A$3000,0))),"") -> 15.03 | H13: =IFERROR(IF(INDEX(營收表現!G$6:G$3000,MATCH($A13,營收表現!$A$6:$A$3000,0))="","",INDEX(營收表現!G$6:G$3000,MATCH($A13,營收表現!$A$6:$A$3000,0))),"") -> 71.36 | I13: =IFERROR(IF(INDEX(營收表現!H$6:H$3000,MATCH($A13,營收表現!$A$6:$A$3000,0))="","",INDEX(營收表現!H$6:H$3000,MATCH($A13,營收表現!$A$6:$A$3000,0))),"") -> -51.5 | J13: =IFERROR(IF(INDEX(營收表現!I$6:I$3000,MATCH($A13,營收表現!$A$6:$A$3000,0))="","",INDEX(營收表現!I$6:I$3000,MATCH($A13,營收表現!$A$6:$A$3000,0))),"") -> -33 | K13: =IFERROR(IF(INDEX(營收表現!J$6:J$3000,MATCH($A13,營收表現!$A$6:$A$3000,0))="","",INDEX(營收表現!J$6:J$3000,MATCH($A13,營收表現!$A$6:$A$3000,0))),"") -> -11.7 | ... N13: =IFERROR(IF(INDEX(營收表現!M$6:M$3000,MATCH($A13,營收表現!$A$6:$A$3000,0))="","",INDEX(營收表現!M$6:M$3000,MATCH($A13,營收表現!$A$6:$A$3000,0))),"") -> -15.29 | O13: =IF(INDEX(營收表現!N$6:N$3000,MATCH($A13,營收表現!$A$6:$A$3000,0))="","",INDEX(營收表現!N$6:N$3000,MATCH($A13,營收表現!$A$6:$A$3000,0))) -> -4.74
... A68: 4306 | B68: =IFERROR(INDEX(營收表現!B$6:B$3000,MATCH($A68,營收表現!$A$6:$A$3000,0)),"") -> 炎洲 | C68: =IFERROR(INDEX(類別!G$4:G$3000,MATCH($A68,類別!$C$4:$C$3000,0)),"") -> 塑膠 | D68: =IFERROR(IF(INDEX(營收表現!C$6:C$3000,MATCH($A68,營收表現!$A$6:$A$3000,0))="","",INDEX(營收表現!C$6:C$3000,MATCH($A68,營收表現!$A$6:$A$3000,0))),"") -> 3.04 | E68: =IFERROR(IF(INDEX(營收表現!D$6:D$3000,MATCH($A68,營收表現!$A$6:$A$3000,0))="","",INDEX(營收表現!D$6:D$3000,MATCH($A68,營收表現!$A$6:$A$3000,0))),"") -> 2.54 | F68: =IFERROR(IF(INDEX(營收表現!E$6:E$3000,MATCH($A68,營收表現!$A$6:$A$3000,0))="","",INDEX(營收表現!E$6:E$3000,MATCH($A68,營收表現!$A$6:$A$3000,0))),"") -> -0.06 | G68: =IFERROR(IF(INDEX(營收表現!F$6:F$3000,MATCH($A68,營收表現!$A$6:$A$3000,0))="","",INDEX(營收表現!F$6:F$3000,MATCH($A68,營收表現!$A$6:$A$3000,0))),"") -> 13.29 | H68: =IFERROR(IF(INDEX(營收表現!G$6:G$3000,MATCH($A68,營收表現!$A$6:$A$3000,0))="","",INDEX(營收表現!G$6:G$3000,MATCH($A68,營收表現!$A$6:$A$3000,0))),"") -> -4.86 | I68: =IFERROR(IF(INDEX(營收表現!H$6:H$3000,MATCH($A68,營收表現!$A$6:$A$3000,0))="","",INDEX(營收表現!H$6:H$3000,MATCH($A68,營收表現!$A$6:$A$3000,0))),"") -> -2.72 | J68: =IFERROR(IF(INDEX(營收表現!I$6:I$3000,MATCH($A68,營收表現!$A$6:$A$3000,0))="","",INDEX(營收表現!I$6:I$3000,MATCH($A68,營收表現!$A$6:$A$3000,0))),"") -> -21.08 | K68: =IFERROR(IF(INDEX(營收表現!J$6:J$3000,MATCH($A68,營收表現!$A$6:$A$3000,0))="","",INDEX(營收表現!J$6:J$3000,MATCH($A68,營收表現!$A$6:$A$3000,0))),"") -> -9.4 | ... N68: =IFERROR(IF(INDEX(營收表現!M$6:M$3000,MATCH($A68,營收表現!$A$6:$A$3000,0))="","",INDEX(營收表現!M$6:M$3000,MATCH($A68,營收表現!$A$6:$A$3000,0))),"") -> 11.94 | O68: =IF(INDEX(營收表現!N$6:N$3000,MATCH($A68,營收表現!$A$6:$A$3000,0))="","",INDEX(營收表現!N$6:N$3000,MATCH($A68,營收表現!$A$6:$A$3000,0))) -> 29.1
B69: =IFERROR(INDEX(營收表現!B$6:B$3000,MATCH($A69,營收表現!$A$6:$A$3000,0)),"") | C69: =IFERROR(INDEX(類別!G$4:G$3000,MATCH($A69,類別!$C$4:$C$3000,0)),"") | D69: =IFERROR(IF(INDEX(營收表現!C$6:C$3000,MATCH($A69,營收表現!$A$6:$A$3000,0))="","",INDEX(營收表現!C$6:C$3000,MATCH($A69,營收表現!$A$6:$A$3000,0))),"") | E69: =IFERROR(IF(INDEX(營收表現!D$6:D$3000,MATCH($A69,營收表現!$A$6:$A$3000,0))="","",INDEX(營收表現!D$6:D$3000,MATCH($A69,營收表現!$A$6:$A$3000,0))),"") | F69: =IFERROR(IF(INDEX(營收表現!E$6:E$3000,MATCH($A69,營收表現!$A$6:$A$3000,0))="","",INDEX(營收表現!E$6:E$3000,MATCH($A69,營收表現!$A$6:$A$3000,0))),"") | G69: =IFERROR(IF(INDEX(營收表現!F$6:F$3000,MATCH($A69,營收表現!$A$6:$A$3000,0))="","",INDEX(營收表現!F$6:F$3000,MATCH($A69,營收表現!$A$6:$A$3000,0))),"") | H69: =IFERROR(IF(INDEX(營收表現!G$6:G$3000,MATCH($A69,營收表現!$A$6:$A$3000,0))="","",INDEX(營收表現!G$6:G$3000,MATCH($A69,營收表現!$A$6:$A$3000,0))),"") | I69: =IFERROR(IF(INDEX(營收表現!H$6:H$3000,MATCH($A69,營收表現!$A$6:$A$3000,0))="","",INDEX(營收表現!H$6:H$3000,MATCH($A69,營收表現!$A$6:$A$3000,0))),"") | J69: =IFERROR(IF(INDEX(營收表現!I$6:I$3000,MATCH($A69,營收表現!$A$6:$A$3000,0))="","",INDEX(營收表現!I$6:I$3000,MATCH($A69,營收表現!$A$6:$A$3000,0))),"") | K69: =IFERROR(IF(INDEX(營收表現!J$6:J$3000,MATCH($A69,營收表現!$A$6:$A$3000,0))="","",INDEX(營收表現!J$6:J$3000,MATCH($A69,營收表現!$A$6:$A$3000,0))),"") | ... O69: =IFERROR(IF(INDEX(營收表現!N$6:N$3000,MATCH($A69,營收表現!$A$6:$A$3000,0))="","",INDEX(營收表現!N$6:N$3000,MATCH($A69,營收表現!$A$6:$A$3000,0))),"")
B70: =IFERROR(INDEX(營收表現!B$6:B$3000,MATCH($A70,營收表現!$A$6:$A$3000,0)),"") | C70: =IFERROR(INDEX(類別!G$4:G$3000,MATCH($A70,類別!$C$4:$C$3000,0)),"") | D70: =IFERROR(IF(INDEX(營收表現!C$6:C$3000,MATCH($A70,營收表現!$A$6:$A$3000,0))="","",INDEX(營收表現!C$6:C$3000,MATCH($A70,營收表現!$A$6:$A$3000,0))),"") | E70: =IFERROR(IF(INDEX(營收表現!D$6:D$3000,MATCH($A70,營收表現!$A$6:$A$3000,0))="","",INDEX(營收表現!D$6:D$3000,MATCH($A70,營收表現!$A$6:$A$3000,0))),"") | F70: =IFERROR(IF(INDEX(營收表現!E$6:E$3000,MATCH($A70,營收表現!$A$6:$A$3000,0))="","",INDEX(營收表現!E$6:E$3000,MATCH($A70,營收表現!$A$6:$A$3000,0))),"") | G70: =IFERROR(IF(INDEX(營收表現!F$6:F$3000,MATCH($A70,營收表現!$A$6:$A$3000,0))="","",INDEX(營收表現!F$6:F$3000,MATCH($A70,營收表現!$A$6:$A$3000,0))),"") | H70: =IFERROR(IF(INDEX(營收表現!G$6:G$3000,MATCH($A70,營收表現!$A$6:$A$3000,0))="","",INDEX(營收表現!G$6:G$3000,MATCH($A70,營收表現!$A$6:$A$3000,0))),"") | I70: =IFERROR(IF(INDEX(營收表現!H$6:H$3000,MATCH($A70,營收表現!$A$6:$A$3000,0))="","",INDEX(營收表現!H$6:H$3000,MATCH($A70,營收表現!$A$6:$A$3000,0))),"") | J70: =IFERROR(IF(INDEX(營收表現!I$6:I$3000,MATCH($A70,營收表現!$A$6:$A$3000,0))="","",INDEX(營收表現!I$6:I$3000,MATCH($A70,營收表現!$A$6:$A$3000,0))),"") | K70: =IFERROR(IF(INDEX(營收表現!J$6:J$3000,MATCH($A70,營收表現!$A$6:$A$3000,0))="","",INDEX(營收表現!J$6:J$3000,MATCH($A70,營收表現!$A$6:$A$3000,0))),"") | ... O70: =IFERROR(IF(INDEX(營收表現!N$6:N$3000,MATCH($A70,營收表現!$A$6:$A$3000,0))="","",INDEX(營收表現!N$6:N$3000,MATCH($A70,營收表現!$A$6:$A$3000,0))),"")
B71: =IFERROR(INDEX(營收表現!B$6:B$3000,MATCH($A71,營收表現!$A$6:$A$3000,0)),"") | C71: =IFERROR(INDEX(類別!G$4:G$3000,MATCH($A71,類別!$C$4:$C$3000,0)),"") | D71: =IFERROR(IF(INDEX(營收表現!C$6:C$3000,MATCH($A71,營收表現!$A$6:$A$3000,0))="","",INDEX(營收表現!C$6:C$3000,MATCH($A71,營收表現!$A$6:$A$3000,0))),"") | E71: =IFERROR(IF(INDEX(營收表現!D$6:D$3000,MATCH($A71,營收表現!$A$6:$A$3000,0))="","",INDEX(營收表現!D$6:D$3000,MATCH($A71,營收表現!$A$6:$A$3000,0))),"") | F71: =IFERROR(IF(INDEX(營收表現!E$6:E$3000,MATCH($A71,營收表現!$A$6:$A$3000,0))="","",INDEX(營收表現!E$6:E$3000,MATCH($A71,營收表現!$A$6:$A$3000,0))),"") | G71: =IFERROR(IF(INDEX(營收表現!F$6:F$3000,MATCH($A71,營收表現!$A$6:$A$3000,0))="","",INDEX(營收表現!F$6:F$3000,MATCH($A71,營收表現!$A$6:$A$3000,0))),"") | H71: =IFERROR(IF(INDEX(營收表現!G$6:G$3000,MATCH($A71,營收表現!$A$6:$A$3000,0))="","",INDEX(營收表現!G$6:G$3000,MATCH($A71,營收表現!$A$6:$A$3000,0))),"") | I71: =IFERROR(IF(INDEX(營收表現!H$6:H$3000,MATCH($A71,營收表現!$A$6:$A$3000,0))="","",INDEX(營收表現!H$6:H$3000,MATCH($A71,營收表現!$A$6:$A$3000,0))),"") | J71: =IFERROR(IF(INDEX(營收表現!I$6:I$3000,MATCH($A71,營收表現!$A$6:$A$3000,0))="","",INDEX(營收表現!I$6:I$3000,MATCH($A71,營收表現!$A$6:$A$3000,0))),"") | K71: =IFERROR(IF(INDEX(營收表現!J$6:J$3000,MATCH($A71,營收表現!$A$6:$A$3000,0))="","",INDEX(營收表現!J$6:J$3000,MATCH($A71,營收表現!$A$6:$A$3000,0))),"") | ... O71: =IFERROR(IF(INDEX(營收表現!N$6:N$3000,MATCH($A71,營收表現!$A$6:$A$3000,0))="","",INDEX(營收表現!N$6:N$3000,MATCH($A71,營收表現!$A$6:$A$3000,0))),"")
B72: =IFERROR(INDEX(營收表現!B$6:B$3000,MATCH($A72,營收表現!$A$6:$A$3000,0)),"") | C72: =IFERROR(INDEX(類別!G$4:G$3000,MATCH($A72,類別!$C$4:$C$3000,0)),"") | D72: =IFERROR(IF(INDEX(營收表現!C$6:C$3000,MATCH($A72,營收表現!$A$6:$A$3000,0))="","",INDEX(營收表現!C$6:C$3000,MATCH($A72,營收表現!$A$6:$A$3000,0))),"") | E72: =IFERROR(IF(INDEX(營收表現!D$6:D$3000,MATCH($A72,營收表現!$A$6:$A$3000,0))="","",INDEX(營收表現!D$6:D$3000,MATCH($A72,營收表現!$A$6:$A$3000,0))),"") | F72: =IFERROR(IF(INDEX(營收表現!E$6:E$3000,MATCH($A72,營收表現!$A$6:$A$3000,0))="","",INDEX(營收表現!E$6:E$3000,MATCH($A72,營收表現!$A$6:$A$3000,0))),"") | G72: =IFERROR(IF(INDEX(營收表現!F$6:F$3000,MATCH($A72,營收表現!$A$6:$A$3000,0))="","",INDEX(營收表現!F$6:F$3000,MATCH($A72,營收表現!$A$6:$A$3000,0))),"") | H72: =IFERROR(IF(INDEX(營收表現!G$6:G$3000,MATCH($A72,營收表現!$A$6:$A$3000,0))="","",INDEX(營收表現!G$6:G$3000,MATCH($A72,營收表現!$A$6:$A$3000,0))),"") | I72: =IFERROR(IF(INDEX(營收表現!H$6:H$3000,MATCH($A72,營收表現!$A$6:$A$3000,0))="","",INDEX(營收表現!H$6:H$3000,MATCH($A72,營收表現!$A$6:$A$3000,0))),"") | J72: =IFERROR(IF(INDEX(營收表現!I$6:I$3000,MATCH($A72,營收表現!$A$6:$A$3000,0))="","",INDEX(營收表現!I$6:I$3000,MATCH($A72,營收表現!$A$6:$A$3000,0))),"") | K72: =IFERROR(IF(INDEX(營收表現!J$6:J$3000,MATCH($A72,營收表現!$A$6:$A$3000,0))="","",INDEX(營收表現!J$6:J$3000,MATCH($A72,營收表現!$A$6:$A$3000,0))),"") | ... O72: =IFERROR(IF(INDEX(營收表現!N$6:N$3000,MATCH($A72,營收表現!$A$6:$A$3000,0))="","",INDEX(營收表現!N$6:N$3000,MATCH($A72,營收表現!$A$6:$A$3000,0))),"")
B73: =IFERROR(INDEX(營收表現!B$6:B$3000,MATCH($A73,營收表現!$A$6:$A$3000,0)),"") | C73: =IFERROR(INDEX(類別!G$4:G$3000,MATCH($A73,類別!$C$4:$C$3000,0)),"") | D73: =IFERROR(IF(INDEX(營收表現!C$6:C$3000,MATCH($A73,營收表現!$A$6:$A$3000,0))="","",INDEX(營收表現!C$6:C$3000,MATCH($A73,營收表現!$A$6:$A$3000,0))),"") | E73: =IFERROR(IF(INDEX(營收表現!D$6:D$3000,MATCH($A73,營收表現!$A$6:$A$3000,0))="","",INDEX(營收表現!D$6:D$3000,MATCH($A73,營收表現!$A$6:$A$3000,0))),"") | F73: =IFERROR(IF(INDEX(營收表現!E$6:E$3000,MATCH($A73,營收表現!$A$6:$A$3000,0))="","",INDEX(營收表現!E$6:E$3000,MATCH($A73,營收表現!$A$6:$A$3000,0))),"") | G73: =IFERROR(IF(INDEX(營收表現!F$6:F$3000,MATCH($A73,營收表現!$A$6:$A$3000,0))="","",INDEX(營收表現!F$6:F$3000,MATCH($A73,營收表現!$A$6:$A$3000,0))),"") | H73: =IFERROR(IF(INDEX(營收表現!G$6:G$3000,MATCH($A73,營收表現!$A$6:$A$3000,0))="","",INDEX(營收表現!G$6:G$3000,MATCH($A73,營收表現!$A$6:$A$3000,0))),"") | I73: =IFERROR(IF(INDEX(營收表現!H$6:H$3000,MATCH($A73,營收表現!$A$6:$A$3000,0))="","",INDEX(營收表現!H$6:H$3000,MATCH($A73,營收表現!$A$6:$A$3000,0))),"") | J73: =IFERROR(IF(INDEX(營收表現!I$6:I$3000,MATCH($A73,營收表現!$A$6:$A$3000,0))="","",INDEX(營收表現!I$6:I$3000,MATCH($A73,營收表現!$A$6:$A$3000,0))),"") | K73: =IFERROR(IF(INDEX(營收表現!J$6:J$3000,MATCH($A73,營收表現!$A$6:$A$3000,0))="","",INDEX(營收表現!J$6:J$3000,MATCH($A73,營收表現!$A$6:$A$3000,0))),"") | ... O73: =IFERROR(IF(INDEX(營收表現!N$6:N$3000,MATCH($A73,營收表現!$A$6:$A$3000,0))="","",INDEX(營收表現!N$6:N$3000,MATCH($A73,營收表現!$A$6:$A$3000,0))),"")
B74: =IFERROR(INDEX(營收表現!B$6:B$3000,MATCH($A74,營收表現!$A$6:$A$3000,0)),"") | C74: =IFERROR(INDEX(類別!G$4:G$3000,MATCH($A74,類別!$C$4:$C$3000,0)),"") | D74: =IFERROR(IF(INDEX(營收表現!C$6:C$3000,MATCH($A74,營收表現!$A$6:$A$3000,0))="","",INDEX(營收表現!C$6:C$3000,MATCH($A74,營收表現!$A$6:$A$3000,0))),"") | E74: =IFERROR(IF(INDEX(營收表現!D$6:D$3000,MATCH($A74,營收表現!$A$6:$A$3000,0))="","",INDEX(營收表現!D$6:D$3000,MATCH($A74,營收表現!$A$6:$A$3000,0))),"") | F74: =IFERROR(IF(INDEX(營收表現!E$6:E$3000,MATCH($A74,營收表現!$A$6:$A$3000,0))="","",INDEX(營收表現!E$6:E$3000,MATCH($A74,營收表現!$A$6:$A$3000,0))),"") | G74: =IFERROR(IF(INDEX(營收表現!F$6:F$3000,MATCH($A74,營收表現!$A$6:$A$3000,0))="","",INDEX(營收表現!F$6:F$3000,MATCH($A74,營收表現!$A$6:$A$3000,0))),"") | H74: =IFERROR(IF(INDEX(營收表現!G$6:G$3000,MATCH($A74,營收表現!$A$6:$A$3000,0))="","",INDEX(營收表現!G$6:G$3000,MATCH($A74,營收表現!$A$6:$A$3000,0))),"") | I74: =IFERROR(IF(INDEX(營收表現!H$6:H$3000,MATCH($A74,營收表現!$A$6:$A$3000,0))="","",INDEX(營收表現!H$6:H$3000,MATCH($A74,營收表現!$A$6:$A$3000,0))),"") | J74: =IFERROR(IF(INDEX(營收表現!I$6:I$3000,MATCH($A74,營收表現!$A$6:$A$3000,0))="","",INDEX(營收表現!I$6:I$3000,MATCH($A74,營收表現!$A$6:$A$3000,0))),"") | K74: =IFERROR(IF(INDEX(營收表現!J$6:J$3000,MATCH($A74,營收表現!$A$6:$A$3000,0))="","",INDEX(營收表現!J$6:J$3000,MATCH($A74,營收表現!$A$6:$A$3000,0))),"") | ... O74: =IFERROR(IF(INDEX(營收表現!N$6:N$3000,MATCH($A74,營收表現!$A$6:$A$3000,0))="","",INDEX(營收表現!N$6:N$3000,MATCH($A74,營收表現!$A$6:$A$3000,0))),"")
B75: =IFERROR(INDEX(營收表現!B$6:B$3000,MATCH($A75,營收表現!$A$6:$A$3000,0)),"") | C75: =IFERROR(INDEX(類別!G$4:G$3000,MATCH($A75,類別!$C$4:$C$3000,0)),"") | D75: =IFERROR(IF(INDEX(營收表現!C$6:C$3000,MATCH($A75,營收表現!$A$6:$A$3000,0))="","",INDEX(營收表現!C$6:C$3000,MATCH($A75,營收表現!$A$6:$A$3000,0))),"") | E75: =IFERROR(IF(INDEX(營收表現!D$6:D$3000,MATCH($A75,營收表現!$A$6:$A$3000,0))="","",INDEX(營收表現!D$6:D$3000,MATCH($A75,營收表現!$A$6:$A$3000,0))),"") | F75: =IFERROR(IF(INDEX(營收表現!E$6:E$3000,MATCH($A75,營收表現!$A$6:$A$3000,0))="","",INDEX(營收表現!E$6:E$3000,MATCH($A75,營收表現!$A$6:$A$3000,0))),"") | G75: =IFERROR(IF(INDEX(營收表現!F$6:F$3000,MATCH($A75,營收表現!$A$6:$A$3000,0))="","",INDEX(營收表現!F$6:F$3000,MATCH($A75,營收表現!$A$6:$A$3000,0))),"") | H75: =IFERROR(IF(INDEX(營收表現!G$6:G$3000,MATCH($A75,營收表現!$A$6:$A$3000,0))="","",INDEX(營收表現!G$6:G$3000,MATCH($A75,營收表現!$A$6:$A$3000,0))),"") | I75: =IFERROR(IF(INDEX(營收表現!H$6:H$3000,MATCH($A75,營收表現!$A$6:$A$3000,0))="","",INDEX(營收表現!H$6:H$3000,MATCH($A75,營收表現!$A$6:$A$3000,0))),"") | J75: =IFERROR(IF(INDEX(營收表現!I$6:I$3000,MATCH($A75,營收表現!$A$6:$A$3000,0))="","",INDEX(營收表現!I$6:I$3000,MATCH($A75,營收表現!$A$6:$A$3000,0))),"") | K75: =IFERROR(IF(INDEX(營收表現!J$6:J$3000,MATCH($A75,營收表現!$A$6:$A$3000,0))="","",INDEX(營收表現!J$6:J$3000,MATCH($A75,營收表現!$A$6:$A$3000,0))),"") | ... O75: =IFERROR(IF(INDEX(營收表現!N$6:N$3000,MATCH($A75,營收表現!$A$6:$A$3000,0))="","",INDEX(營收表現!N$6:N$3000,MATCH($A75,營收表現!$A$6:$A$3000,0))),"")
B76: =IFERROR(INDEX(營收表現!B$6:B$3000,MATCH($A76,營收表現!$A$6:$A$3000,0)),"") | C76: =IFERROR(INDEX(類別!G$4:G$3000,MATCH($A76,類別!$C$4:$C$3000,0)),"") | D76: =IFERROR(IF(INDEX(營收表現!C$6:C$3000,MATCH($A76,營收表現!$A$6:$A$3000,0))="","",INDEX(營收表現!C$6:C$3000,MATCH($A76,營收表現!$A$6:$A$3000,0))),"") | E76: =IFERROR(IF(INDEX(營收表現!D$6:D$3000,MATCH($A76,營收表現!$A$6:$A$3000,0))="","",INDEX(營收表現!D$6:D$3000,MATCH($A76,營收表現!$A$6:$A$3000,0))),"") | F76: =IFERROR(IF(INDEX(營收表現!E$6:E$3000,MATCH($A76,營收表現!$A$6:$A$3000,0))="","",INDEX(營收表現!E$6:E$3000,MATCH($A76,營收表現!$A$6:$A$3000,0))),"") | G76: =IFERROR(IF(INDEX(營收表現!F$6:F$3000,MATCH($A76,營收表現!$A$6:$A$3000,0))="","",INDEX(營收表現!F$6:F$3000,MATCH($A76,營收表現!$A$6:$A$3000,0))),"") | H76: =IFERROR(IF(INDEX(營收表現!G$6:G$3000,MATCH($A76,營收表現!$A$6:$A$3000,0))="","",INDEX(營收表現!G$6:G$3000,MATCH($A76,營收表現!$A$6:$A$3000,0))),"") | I76: =IFERROR(IF(INDEX(營收表現!H$6:H$3000,MATCH($A76,營收表現!$A$6:$A$3000,0))="","",INDEX(營收表現!H$6:H$3000,MATCH($A76,營收表現!$A$6:$A$3000,0))),"") | J76: =IFERROR(IF(INDEX(營收表現!I$6:I$3000,MATCH($A76,營收表現!$A$6:$A$3000,0))="","",INDEX(營收表現!I$6:I$3000,MATCH($A76,營收表現!$A$6:$A$3000,0))),"") | K76: =IFERROR(IF(INDEX(營收表現!J$6:J$3000,MATCH($A76,營收表現!$A$6:$A$3000,0))="","",INDEX(營收表現!J$6:J$3000,MATCH($A76,營收表現!$A$6:$A$3000,0))),"") | ... O76: =IFERROR(IF(INDEX(營收表現!N$6:N$3000,MATCH($A76,營收表現!$A$6:$A$3000,0))="","",INDEX(營收表現!N$6:N$3000,MATCH($A76,營收表現!$A$6:$A$3000,0))),"")
B77: =IFERROR(INDEX(營收表現!B$6:B$3000,MATCH($A77,營收表現!$A$6:$A$3000,0)),"") | C77: =IFERROR(INDEX(類別!G$4:G$3000,MATCH($A77,類別!$C$4:$C$3000,0)),"") | D77: =IFERROR(IF(INDEX(營收表現!C$6:C$3000,MATCH($A77,營收表現!$A$6:$A$3000,0))="","",INDEX(營收表現!C$6:C$3000,MATCH($A77,營收表現!$A$6:$A$3000,0))),"") | E77: =IFERROR(IF(INDEX(營收表現!D$6:D$3000,MATCH($A77,營收表現!$A$6:$A$3000,0))="","",INDEX(營收表現!D$6:D$3000,MATCH($A77,營收表現!$A$6:$A$3000,0))),"") | F77: =IFERROR(IF(INDEX(營收表現!E$6:E$3000,MATCH($A77,營收表現!$A$6:$A$3000,0))="","",INDEX(營收表現!E$6:E$3000,MATCH($A77,營收表現!$A$6:$A$3000,0))),"") | G77: =IFERROR(IF(INDEX(營收表現!F$6:F$3000,MATCH($A77,營收表現!$A$6:$A$3000,0))="","",INDEX(營收表現!F$6:F$3000,MATCH($A77,營收表現!$A$6:$A$3000,0))),"") | H77: =IFERROR(IF(INDEX(營收表現!G$6:G$3000,MATCH($A77,營收表現!$A$6:$A$3000,0))="","",INDEX(營收表現!G$6:G$3000,MATCH($A77,營收表現!$A$6:$A$3000,0))),"") | I77: =IFERROR(IF(INDEX(營收表現!H$6:H$3000,MATCH($A77,營收表現!$A$6:$A$3000,0))="","",INDEX(營收表現!H$6:H$3000,MATCH($A77,營收表現!$A$6:$A$3000,0))),"") | J77: =IFERROR(IF(INDEX(營收表現!I$6:I$3000,MATCH($A77,營收表現!$A$6:$A$3000,0))="","",INDEX(營收表現!I$6:I$3000,MATCH($A77,營收表現!$A$6:$A$3000,0))),"") | K77: =IFERROR(IF(INDEX(營收表現!J$6:J$3000,MATCH($A77,營收表現!$A$6:$A$3000,0))="","",INDEX(營收表現!J$6:J$3000,MATCH($A77,營收表現!$A$6:$A$3000,0))),"") | ... O77: =IFERROR(IF(INDEX(營收表現!N$6:N$3000,MATCH($A77,營收表現!$A$6:$A$3000,0))="","",INDEX(營收表現!N$6:N$3000,MATCH($A77,營收表現!$A$6:$A$3000,0))),"")
B78: =IFERROR(INDEX(營收表現!B$6:B$3000,MATCH($A78,營收表現!$A$6:$A$3000,0)),"") | C78: =IFERROR(INDEX(類別!G$4:G$3000,MATCH($A78,類別!$C$4:$C$3000,0)),"") | D78: =IFERROR(IF(INDEX(營收表現!C$6:C$3000,MATCH($A78,營收表現!$A$6:$A$3000,0))="","",INDEX(營收表現!C$6:C$3000,MATCH($A78,營收表現!$A$6:$A$3000,0))),"") | E78: =IFERROR(IF(INDEX(營收表現!D$6:D$3000,MATCH($A78,營收表現!$A$6:$A$3000,0))="","",INDEX(營收表現!D$6:D$3000,MATCH($A78,營收表現!$A$6:$A$3000,0))),"") | F78: =IFERROR(IF(INDEX(營收表現!E$6:E$3000,MATCH($A78,營收表現!$A$6:$A$3000,0))="","",INDEX(營收表現!E$6:E$3000,MATCH($A78,營收表現!$A$6:$A$3000,0))),"") | G78: =IFERROR(IF(INDEX(營收表現!F$6:F$3000,MATCH($A78,營收表現!$A$6:$A$3000,0))="","",INDEX(營收表現!F$6:F$3000,MATCH($A78,營收表現!$A$6:$A$3000,0))),"") | H78: =IFERROR(IF(INDEX(營收表現!G$6:G$3000,MATCH($A78,營收表現!$A$6:$A$3000,0))="","",INDEX(營收表現!G$6:G$3000,MATCH($A78,營收表現!$A$6:$A$3000,0))),"") | I78: =IFERROR(IF(INDEX(營收表現!H$6:H$3000,MATCH($A78,營收表現!$A$6:$A$3000,0))="","",INDEX(營收表現!H$6:H$3000,MATCH($A78,營收表現!$A$6:$A$3000,0))),"") | J78: =IFERROR(IF(INDEX(營收表現!I$6:I$3000,MATCH($A78,營收表現!$A$6:$A$3000,0))="","",INDEX(營收表現!I$6:I$3000,MATCH($A78,營收表現!$A$6:$A$3000,0))),"") | K78: =IFERROR(IF(INDEX(營收表現!J$6:J$3000,MATCH($A78,營收表現!$A$6:$A$3000,0))="","",INDEX(營收表現!J$6:J$3000,MATCH($A78,營收表現!$A$6:$A$3000,0))),"") | ... O78: =IFERROR(IF(INDEX(營收表現!N$6:N$3000,MATCH($A78,營收表現!$A$6:$A$3000,0))="","",INDEX(營收表現!N$6:N$3000,MATCH($A78,營收表現!$A$6:$A$3000,0))),"")
B79: =IFERROR(INDEX(營收表現!B$6:B$3000,MATCH($A79,營收表現!$A$6:$A$3000,0)),"") | C79: =IFERROR(INDEX(類別!G$4:G$3000,MATCH($A79,類別!$C$4:$C$3000,0)),"") | D79: =IFERROR(IF(INDEX(營收表現!C$6:C$3000,MATCH($A79,營收表現!$A$6:$A$3000,0))="","",INDEX(營收表現!C$6:C$3000,MATCH($A79,營收表現!$A$6:$A$3000,0))),"") | E79: =IFERROR(IF(INDEX(營收表現!D$6:D$3000,MATCH($A79,營收表現!$A$6:$A$3000,0))="","",INDEX(營收表現!D$6:D$3000,MATCH($A79,營收表現!$A$6:$A$3000,0))),"") | F79: =IFERROR(IF(INDEX(營收表現!E$6:E$3000,MATCH($A79,營收表現!$A$6:$A$3000,0))="","",INDEX(營收表現!E$6:E$3000,MATCH($A79,營收表現!$A$6:$A$3000,0))),"") | G79: =IFERROR(IF(INDEX(營收表現!F$6:F$3000,MATCH($A79,營收表現!$A$6:$A$3000,0))="","",INDEX(營收表現!F$6:F$3000,MATCH($A79,營收表現!$A$6:$A$3000,0))),"") | H79: =IFERROR(IF(INDEX(營收表現!G$6:G$3000,MATCH($A79,營收表現!$A$6:$A$3000,0))="","",INDEX(營收表現!G$6:G$3000,MATCH($A79,營收表現!$A$6:$A$3000,0))),"") | I79: =IFERROR(IF(INDEX(營收表現!H$6:H$3000,MATCH($A79,營收表現!$A$6:$A$3000,0))="","",INDEX(營收表現!H$6:H$3000,MATCH($A79,營收表現!$A$6:$A$3000,0))),"") | J79: =IFERROR(IF(INDEX(營收表現!I$6:I$3000,MATCH($A79,營收表現!$A$6:$A$3000,0))="","",INDEX(營收表現!I$6:I$3000,MATCH($A79,營收表現!$A$6:$A$3000,0))),"") | K79: =IFERROR(IF(INDEX(營收表現!J$6:J$3000,MATCH($A79,營收表現!$A$6:$A$3000,0))="","",INDEX(營收表現!J$6:J$3000,MATCH($A79,營收表現!$A$6:$A$3000,0))),"") | ... O79: =IFERROR(IF(INDEX(營收表現!N$6:N$3000,MATCH($A79,營收表現!$A$6:$A$3000,0))="","",INDEX(營收表現!N$6:N$3000,MATCH($A79,營收表現!$A$6:$A$3000,0))),"")
B80: =IFERROR(INDEX(營收表現!B$6:B$3000,MATCH($A80,營收表現!$A$6:$A$3000,0)),"") | C80: =IFERROR(INDEX(類別!G$4:G$3000,MATCH($A80,類別!$C$4:$C$3000,0)),"") | D80: =IFERROR(IF(INDEX(營收表現!C$6:C$3000,MATCH($A80,營收表現!$A$6:$A$3000,0))="","",INDEX(營收表現!C$6:C$3000,MATCH($A80,營收表現!$A$6:$A$3000,0))),"") | E80: =IFERROR(IF(INDEX(營收表現!D$6:D$3000,MATCH($A80,營收表現!$A$6:$A$3000,0))="","",INDEX(營收表現!D$6:D$3000,MATCH($A80,營收表現!$A$6:$A$3000,0))),"") | F80: =IFERROR(IF(INDEX(營收表現!E$6:E$3000,MATCH($A80,營收表現!$A$6:$A$3000,0))="","",INDEX(營收表現!E$6:E$3000,MATCH($A80,營收表現!$A$6:$A$3000,0))),"") | G80: =IFERROR(IF(INDEX(營收表現!F$6:F$3000,MATCH($A80,營收表現!$A$6:$A$3000,0))="","",INDEX(營收表現!F$6:F$3000,MATCH($A80,營收表現!$A$6:$A$3000,0))),"") | H80: =IFERROR(IF(INDEX(營收表現!G$6:G$3000,MATCH($A80,營收表現!$A$6:$A$3000,0))="","",INDEX(營收表現!G$6:G$3000,MATCH($A80,營收表現!$A$6:$A$3000,0))),"") | I80: =IFERROR(IF(INDEX(營收表現!H$6:H$3000,MATCH($A80,營收表現!$A$6:$A$3000,0))="","",INDEX(營收表現!H$6:H$3000,MATCH($A80,營收表現!$A$6:$A$3000,0))),"") | J80: =IFERROR(IF(INDEX(營收表現!I$6:I$3000,MATCH($A80,營收表現!$A$6:$A$3000,0))="","",INDEX(營收表現!I$6:I$3000,MATCH($A80,營收表現!$A$6:$A$3000,0))),"") | K80: =IFERROR(IF(INDEX(營收表現!J$6:J$3000,MATCH($A80,營收表現!$A$6:$A$3000,0))="","",INDEX(營收表現!J$6:J$3000,MATCH($A80,營收表現!$A$6:$A$3000,0))),"") | ... O80: =IFERROR(IF(INDEX(營收表現!N$6:N$3000,MATCH($A80,營收表現!$A$6:$A$3000,0))="","",INDEX(營收表現!N$6:N$3000,MATCH($A80,營收表現!$A$6:$A$3000,0))),"")
... B158: =IFERROR(INDEX(營收表現!B$6:B$3000,MATCH($A158,營收表現!$A$6:$A$3000,0)),"") | C158: =IFERROR(INDEX(類別!G$4:G$3000,MATCH($A158,類別!$C$4:$C$3000,0)),"") | D158: =IFERROR(IF(INDEX(營收表現!C$6:C$3000,MATCH($A158,營收表現!$A$6:$A$3000,0))="","",INDEX(營收表現!C$6:C$3000,MATCH($A158,營收表現!$A$6:$A$3000,0))),"") | E158: =IFERROR(IF(INDEX(營收表現!D$6:D$3000,MATCH($A158,營收表現!$A$6:$A$3000,0))="","",INDEX(營收表現!D$6:D$3000,MATCH($A158,營收表現!$A$6:$A$3000,0))),"") | F158: =IFERROR(IF(INDEX(營收表現!E$6:E$3000,MATCH($A158,營收表現!$A$6:$A$3000,0))="","",INDEX(營收表現!E$6:E$3000,MATCH($A158,營收表現!$A$6:$A$3000,0))),"") | G158: =IFERROR(IF(INDEX(營收表現!F$6:F$3000,MATCH($A158,營收表現!$A$6:$A$3000,0))="","",INDEX(營收表現!F$6:F$3000,MATCH($A158,營收表現!$A$6:$A$3000,0))),"") | H158: =IFERROR(IF(INDEX(營收表現!G$6:G$3000,MATCH($A158,營收表現!$A$6:$A$3000,0))="","",INDEX(營收表現!G$6:G$3000,MATCH($A158,營收表現!$A$6:$A$3000,0))),"") | I158: =IFERROR(IF(INDEX(營收表現!H$6:H$3000,MATCH($A158,營收表現!$A$6:$A$3000,0))="","",INDEX(營收表現!H$6:H$3000,MATCH($A158,營收表現!$A$6:$A$3000,0))),"") | J158: =IFERROR(IF(INDEX(營收表現!I$6:I$3000,MATCH($A158,營收表現!$A$6:$A$3000,0))="","",INDEX(營收表現!I$6:I$3000,MATCH($A158,營收表現!$A$6:$A$3000,0))),"") | K158: =IFERROR(IF(INDEX(營收表現!J$6:J$3000,MATCH($A158,營收表現!$A$6:$A$3000,0))="","",INDEX(營收表現!J$6:J$3000,MATCH($A158,營收表現!$A$6:$A$3000,0))),"") | ... O158: =IFERROR(IF(INDEX(營收表現!N$6:N$3000,MATCH($A158,營收表現!$A$6:$A$3000,0))="","",INDEX(營收表現!N$6:N$3000,MATCH($A158,營收表現!$A$6:$A$3000,0))),"")

Sheet Links
A1: 上游代號 | B1: 下游代號 | C1: 關係類型 | D1: 備註
A2: 2338 | B2: 2330 | C2: 光罩/光罩版 | D2: 示例
A3: 2449 | B3: 2330 | C3: IC封測 | D3: 示例
A4: 3680 | B4: 2330 | C4: 夾具/傳送盒 | D4: 示例
A5: 2330 | B5: 2454 | C5: 通訊晶片代工 | D5: 示例
A6: 2308 | B6: 2454 | C6: 電源/電源模組 | D6: 示例
A7: 3711 | B7: 2330 | C7: IC封測
A8: 1711 | B8: 2330 | C8: 半導體化學品
A9: 1727 | B9: 2330 | C9: 半導體化學品
A10: 1717 | B10: 2330 | C10: 半導體化學品
A11: 6239 | B11: 2330 | C11: IC封測
A12: 9933 | B12: 2330 | C12: 工程顧問
A13: 8234 | B13: 2330 | C13: 工業電腦
A14: 1560 | B14: 2330 | C14: 半導體材料
A15: 5434 | B15: 2330 | C15: 半導體材料
A16: 6532 | B16: 2330 | C16: 半導體材料通路商
A17: 3167 | B17: 2330 | C17: 半導體設備
A18: 3580 | B18: 2330 | C18: 半導體設備
A19: 3131 | B19: 2330 | C19: 半導體設備
A20: 5443 | B20: 2330 | C20: 半導體設備
A21: 2467 | B21: 2330 | C21: 半導體設備
A22: 3583 | B22: 2330 | C22: 半導體設備
... A65: 4306 | B65: 2330 | C65: 檢測驗證

Sheet ChainNodes
A1: 節點ID | B1: 名稱 | C1: 順序
A2: 1 | B2: IC設計軟體 | C2: 1
A3: 2 | B3: IC設計 | C3: 2
A4: 3 | B4: 設計IP | C4: 3
A5: 4 | B5: 矽晶圓 | C5: 4
A6: 5 | B6: 光罩 | C6: 5
A7: 6 | B7: 晶圓代工 | C7: 6
A8: 7 | B8: IC封裝 | C8: 7
A9: 8 | B9: 導線架 | C9: 8
A10: 9 | B10: BGA基板 | C10: 9
A11: 10 | B11: IC測試 | C11: 10
A12: 11 | B12: IC基板 | C12: 9
A13: 12 | B13: DRAM | C13: 11
A14: 13 | B14: 類比IC | C14: 12

Sheet ChainLinks
A1: source | B1: target
A2: 1 | B2: 2
A3: 2 | B3: 3
A4: 3 | B4: 6
A5: 4 | B5: 6
A6: 5 | B6: 6
A7: 6 | B7: 7
A8: 7 | B8: 8
A9: 7 | B9: 9
A10: 9 | B10: 10

Sheet ChainStocks
A1: 節點ID | B1: 個股 | C1: 名稱
A2: 6 | B2: 2330 | C2: 台積電
A3: 6 | B3: 2303 | C3: 聯電
A4: 6 | B4: 5347 | C4: 世界先進
A5: 7 | B5: 3711 | C5: 日月光投控
A6: 7 | B6: 2325 | C6: 矽品
A7: 5 | B7: 2338 | C7: 光罩

Sheet README
A1: 使用說明
A2: 1. Revenue：每家公司一列；月份欄位命名必須為 YYYYMM單月合併營收年成長(%) / YYYYMM單月合併營收月變動(%)。
A3: 2. Links：方向為 上游代號 ➜ 下游代號；關係類型與權重可自由維護。
A4: 3. 將本檔命名為 data.xlsx，與 index.html 放在同一層，部署到 GitHub Pages 即可。

Sheet 營收表現
A1: 格式：一般排行///文字///日期//否//否 | B1: 表格欄位/代號種類^=^S^;^週期編號^=^D^;^AllCMenuIDs^=^M009,M009^;^是否轉置^=^False^;^檢視方式^=^2^;^AllFields^=^單月合併營收月變動(%),單月合併營收年成長(%)^;^MainTable^=^^;^ListType^=^^;^SelectDate^=^TOP 6|TOP 6^;^SelectCMenuID^=^M009^;^SelectDate種類^=^1|1^;^AllFieldsNO^=^,^;^自訂欄位公式^=^|^;^自訂欄位Where條件^=^|^;^多期數值處理方式^=^1|1^;^多欄指定個股方式^=^^;^多欄指定個股^=^^;^多欄指定群組名稱^=^^;^欄位顯示狀態^=^1|1^;^欄位轉換日期方式^=^月|月^;^欄位排序方式^=^|^;^欄位採用各期最新^=^|^;^樣本表系統定義全部代號^=^^;^單項目比較欄位^=^^;^單項目比較欄位編號^=^^;^表格類型^=^ | C1: 月營收(成長與達成率).單月合併營收月變動(%)/每一期/最近/6/遞增/月// | D1: 月營收(成長與達成率).單月合併營收月變動(%) | E1: 月營收(成長與達成率).單月合併營收月變動(%) | F1: 月營收(成長與達成率).單月合併營收月變動(%) | G1: 月營收(成長與達成率).單月合併營收月變動(%) | H1: 月營收(成長與達成率).單月合併營收月變動(%) | I1: 月營收(成長與達成率).單月合併營收年成長(%)/每一期/最近/6/遞增/月// | J1: 月營收(成長與達成率).單月合併營收年成長(%) | K1: 月營收(成長與達成率).單月合併營收年成長(%) | L1: 月營收(成長與達成率).單月合併營收年成長(%) | M1: 月營收(成長與達成率).單月合併營收年成長(%) | N1: 月營收(成長與達成率).單月合併營收年成長(%)
A2: 基準日:最近一日 | B2: 資料日期/
A3: 更新標題:否 | B3: 參考標題 | C3: 202508單月合併營收月變動(%) | D3: 202509單月合併營收月變動(%) | E3: 202510單月合併營收月變動(%) | F3: 202511單月合併營收月變動(%) | G3: 202512單月合併營收月變動(%) | H3: 202601單月合併營收月變動(%) | I3: 202508單月合併營收年成長(%) | J3: 202509單月合併營收年成長(%) | K3: 202510單月合併營收年成長(%) | L3: 202511單月合併營收年成長(%) | M3: 202512單月合併營收年成長(%) | N3: 202601單月合併營收年成長(%)
A5: 股票代號 | B5: 股票名稱
A6: 1101 | B6: 台泥 | C6: -9.76 | D6: 8.94 | E6: 4.33 | F6: -5.48 | G6: 8.37 | H6: -13.83 | I6: -6.07 | J6: -0.14 | K6: -14.69 | L6: -20.49 | M6: -14.04 | N6: 0.32
A7: 1102 | B7: 亞泥 | C7: -2.96 | D7: 12.79 | E7: -8.69 | F7: 0.89 | G7: 4.88 | H7: -3.01 | I7: -15.89 | J7: -1.67 | K7: -11.25 | L7: -18.19 | M7: -12.88 | N7: 1.86
A8: 1103 | B8: 嘉泥 | C8: -5.95 | D8: -0.83 | E8: 5.02 | F8: 0.97 | G8: 10.34 | I8: -11.41 | J8: -6.02 | K8: 8.01 | L8: -3.89 | M8: -3.28
A9: 1104 | B9: 環泥 | C9: 4.86 | D9: 17.3 | E9: 2.21 | F9: -11.93 | G9: 22.35 | I9: -7.58 | J9: 18.05 | K9: 12.64 | L9: -6.76 | M9: 3.15
A10: 1108 | B10: 幸福 | C10: -3.71 | D10: 1.86 | E10: -7 | F10: 0.1 | G10: 14.31 | H10: 0.43 | I10: -9.97 | J10: -16.07 | K10: -18.03 | L10: -20.55 | M10: -25.92 | N10: -16.41
A11: 1109 | B11: 信大 | C11: -0.72 | D11: 3.93 | E11: -14.15 | F11: 8.84 | G11: 17.15 | H11: -10.07 | I11: 1.69 | J11: 19.49 | K11: -6.48 | L11: -6.21 | M11: 4.63 | N11: 22.73
A12: 1110 | B12: 東泥 | C12: 23.96 | D12: -4.12 | E12: 16.14 | F12: -20.16 | G12: 12.46 | H12: -15.88 | I12: -27.81 | J12: -21.69 | K12: 5.25 | L12: -27.68 | M12: -9.32 | N12: -16.09
A13: 1201 | B13: 味全 | C13: 6.72 | D13: 9.41 | E13: -16.61 | F13: -8.34 | G13: 1.17 | H13: 0.32 | I13: -10.93 | J13: 1.21 | K13: -11.93 | L13: -9.82 | M13: -9.69 | N13: -12.38
A14: 1203 | B14: 味王 | C14: 7.16 | D14: -4.56 | E14: -0.09 | F14: -3.22 | G14: 0.2 | H14: 6.16 | I14: -5.28 | J14: -4.02 | K14: -16.54 | L14: -24.31 | M14: -27.8 | N14: -14.52
A15: 1210 | B15: 大成 | C15: 7.84 | D15: 2.05 | E15: -3.41 | F15: 5.03 | G15: 8.29 | H15: 1.41 | I15: -5.22 | J15: 1.35 | K15: -1.98 | L15: -1.23 | M15: 4.65 | N15: 12
A16: 1213 | B16: 大飲 | C16: 46.76 | D16: -0.14 | E16: -24.18 | F16: -8.19 | G16: -11.82 | H16: 18.15 | I16: 31.97 | J16: 85.2 | K16: 37.93 | L16: 43.82 | M16: 24.48 | N16: 10.6
A17: 1215 | B17: 卜蜂 | C17: -1.63 | D17: 2.4 | E17: -1.75 | F17: 5.75 | G17: 10.78 | H17: -4.18 | I17: -3.49 | J17: 5.08 | K17: -4.49 | L17: 1.93 | M17: 13.02 | N17: 13.03
A18: 1216 | B18: 統一 | C18: 6.45 | D18: -3.92 | E18: -7.17 | F18: -5.65 | G18: 2.25 | H18: 26.37 | I18: -1.34 | J18: 0.97 | K18: -0.77 | L18: -1.12 | M18: 1.69 | N18: 0.53
A19: 1217 | B19: 愛之味 | C19: 21.57 | D19: -11.21 | E19: -30.62 | F19: -11.12 | G19: -2.82 | H19: 46.69 | I19: -14.86 | J19: 7.86 | K19: 1.24 | L19: -10.5 | M19: -5.28 | N19: -1.52
A20: 1218 | B20: 泰山 | C20: 14.28 | D20: -13.3 | E20: -10.62 | F20: -4.5 | G20: 10.17 | H20: 13.3 | I20: -0.39 | J20: -10.13 | K20: -5.02 | L20: -10.13 | M20: 14.31 | N20: 6.3
A21: 1219 | B21: 福壽 | C21: 4.08 | D21: 5.31 | E21: 4.57 | F21: -5.05 | G21: 10.79 | H21: -4.55 | I21: -1.1 | J21: 3.36 | K21: 2.73 | L21: -5.36 | M21: 5.09 | N21: 7.89
... A24: 1227 | B24: 佳格 | C24: 22.92 | D24: 25.79 | E24: -27.75 | F24: 21.2 | G24: 6.24 | H24: 36.85 | I24: -8.81 | J24: 3 | K24: 3.58 | L24: -5.4 | M24: -17.09 | N24: 16.14
A25: 1229 | B25: 聯華 | C25: 3.93 | D25: 21.43 | E25: -17.81 | F25: 25.4 | G25: 7.42 | I25: 10.78 | J25: 34.75 | K25: 21.91 | L25: 14.69 | M25: 11.25
A26: 1231 | B26: 聯華食 | C26: 2.08 | D26: -8.55 | E26: -0.94 | F26: -3.71 | G26: 27.88 | H26: -2.46 | I26: 1.74 | J26: 16.02 | K26: 0.95 | L26: 0.24 | M26: -6.7 | N26: -1.42
A27: 1232 | B27: 大統益 | C27: 1.23 | D27: 0.91 | E27: 3.59 | F27: -2.08 | G27: 9.4 | H27: 11.02 | I27: -1.65 | J27: 3.1 | K27: 0.13 | L27: -3.15 | M27: 2.22 | N27: 21.05
A28: 1233 | B28: 天仁 | C28: 11.25 | D28: 4.78 | E28: -3.23 | F28: -2.75 | G28: 15.24 | H28: -2.34 | I28: -3.74 | J28: 1.81 | K28: 12.21 | L28: -8.96 | M28: -4.25 | N28: -10.05
A29: 1234 | B29: 黑松 | C29: 4.93 | D29: -1.17 | E29: 0.05 | F29: -22.06 | G29: -6.39 | H29: 24.02 | I29: -20.66 | J29: -7.04 | K29: 17.06 | L29: -16.45 | M29: -9.57 | N29: -5.71
A30: 1235 | B30: 興泰 | C30: 46.42 | D30: 3.69 | E30: 2.58 | F30: 22.97 | G30: -54.11 | H30: 110.02 | I30: 41.92 | J30: 46.35 | K30: 40.5 | L30: 88.03 | M30: -1.99 | N30: 177.24
A31: 1236 | B31: 宏亞 | C31: 20.12 | D31: 40.7 | E31: -49.44 | F31: 3.98 | G31: 62.83 | H31: 54.25 | I31: 2.88 | J31: 26.05 | K31: -12.91 | L31: -23.51 | M31: -25.79 | N31: 2.91
A32: 1240 | B32: 茂生農經 | C32: 7.66 | D32: 8.56 | E32: -6.09 | F32: -5.29 | G32: 8.26 | H32: -10.33 | I32: -4.05 | J32: 14.81 | K32: -3.34 | L32: -6.19 | M32: -7.43 | N32: -6.64
A33: 1256 | B33: 鮮活果汁-KY | C33: 1.81 | D33: -18.79 | E33: -44.68 | F33: 3.55 | G33: 70.02 | H33: 9.63 | I33: 23.33 | J33: -2.95 | K33: 12.73 | L33: 24.45 | M33: 74.52 | N33: 36.27
A34: 1259 | B34: 安心 | C34: 1.5 | D34: -2.63 | E34: 2.61 | F34: -2.84 | G34: 0.87 | H34: 0.56 | I34: -3.17 | J34: 0.51 | K34: 4.44 | L34: 1.73 | M34: 3.67 | N34: -4.14
A35: 1264 | B35: 德麥 | C35: -3.57 | D35: 19.04 | E35: -18.24 | F35: 7.58 | G35: 24.55 | H35: 5.08 | I35: -13.27 | J35: 4.91 | K35: -1.38 | L35: -7.88 | M35: -8.59 | N35: 5.78
A36: 1268 | B36: 漢來美食 | C36: 7.57 | D36: 3.59 | E36: 0.61 | F36: 4.83 | G36: 2.56 | H36: 17.38 | I36: 5.02 | J36: -1.46 | K36: 16.57 | L36: 10.77 | M36: -3.41 | N36: -16.81
A37: 1294 | B37: 漢田生技 | C37: 19.67 | D37: 2.34 | E37: -14.3 | F37: 16.72 | G37: 19.38 | H37: 8.11 | I37: -3.92 | J37: 39.8 | K37: 43.72 | L37: 30.35 | M37: 45.41 | N37: 117.94
... A42: 1305 | B42: 華夏 | C42: 2.13 | D42: -3.21 | E42: -25.01 | F42: 11.34 | G42: 5.62 | H42: 22.87 | I42: 19.43 | J42: -19.24 | K42: -32.56 | L42: -35.93 | M42: -12.12 | N42: 3.98
A43: 1307 | B43: 三芳 | C43: -1.04 | D43: -1.59 | E43: -2.27 | F43: -6.97 | G43: -6.01 | I43: -13.82 | J43: 1.32 | K43: 6.79 | L43: -5.85 | M43: -1.11
A44: 1308 | B44: 亞聚 | C44: -1.24 | D44: 17.57 | E44: -18.55 | F44: 6.27 | G44: 5.6 | H44: -9.34 | I44: -1.99 | J44: 41.17 | K44: -5.45 | L44: -12.14 | M44: -10.85 | N44: 2.43
A45: 1309 | B45: 台達化 | C45: -6.54 | D45: 7.35 | E45: -8.57 | F45: -14.16 | G45: 14.64 | H45: 8.93 | I45: -42.78 | J45: -30.99 | K45: -28.6 | L45: -45.35 | M45: -33.03 | N45: -11.65
A46: 1310 | B46: 台苯 | C46: -8.37 | D46: 0.85 | E46: -17.61 | F46: -2.63 | G46: -7.7 | H46: 31.84 | I46: -30.93 | J46: -24.81 | K46: -22.65 | L46: -39.8 | M46: -46.33 | N46: -19.58
A47: 1312 | B47: 國喬 | C47: -15.95 | D47: 67.78 | E47: 7.87 | F47: -8.26 | G47: 12.8 | H47: -1.48 | I47: -16.45 | J47: 75.95 | K47: 117.8 | L47: 58.54 | M47: 64.75 | N47: 84.42
...

Sheet 類別
D1: 2 | E1: 3 | F1: 4 | G1: 5 | H1: 6 | I1: 7 | K1: 2 | N1: 11 | O1: 12 | R1: 5
C3: 代碼/ | D3: 股名 | E3: Cmoney 產業分類 | F3: 研究部 分類 次產業 | G3: 個服部 分類 次產業 | H3: 指標 股 | I3: 市值 | J3: 資料庫 更新 時間 | K3: 是否為0050 | L3: 個服部 產業分類 | M3: 繪圖特用 | N3: 詳細業務 | O3: 概念標籤 | P3: 備用1 | Q3: 備用2 | R3: 個服部 分類 次產業(加未分類)
C4: 1101 | D4: 台泥 | E4: 傳產-水泥 | F4: 水泥營建 | G4: 水泥建材 | H4: Yes | I4: 1860.3 | J4: 45526 | K4: YES | L4: 水泥建材 | M4: 水泥建材 | N4: 水泥、電廠開發(火力、太陽能、 風力、地熱)、储能、充電樁、鋰電池 | R4: 水泥建材
C5: 1102 | D5: 亞泥 | E5: 傳產-水泥 | F5: 水泥營建 | G5: 水泥建材 | H5: Yes | I5: 1471.8 | L5: 食品 | M5: 食品 | N5: 水泥、電廠開發(天然氣) | R5: 水泥建材
C6: 1103 | D6: 嘉泥 | E6: 傳產-水泥 | F6: 水泥營建 | G6: 水泥建材 | I6: 113.4 | L6: 塑膠 | M6: 塑膠 | N6: 水泥、生產、銷售 | R6: 水泥建材
C7: 1104 | D7: 環泥 | E7: 傳產-水泥 | F7: 水泥營建 | G7: 水泥建材 | I7: 187.8 | L7: 營建與營造 | M7: 營建與 營造 | N7: 水泥及預拌混凝土之製造與銷售、石膏板之生產、加工及銷售與進、出口、代理銷售、其餘請參考本公司登記營業項目、 | R7: 水泥建材
C8: 1108 | D8: 幸福 | E8: 傳產-水泥 | F8: 水泥營建 | G8: 水泥建材 | I8: 59.7 | L8: 汽機車零組件 | M8: 汽機車 零組件 | N8: 有關水泥及水泥製品之工業及相關事業 | R8: 水泥建材
C9: 1109 | D9: 信大 | E9: 傳產-水泥 | F9: 水泥營建 | G9: 水泥建材 | I9: 56.8 | L9: 製鞋與紡纖 | M9: 製鞋與 紡纖 | N9: 有關水泥及水泥製品之生產及運銷 | R9: 水泥建材
C10: 1110 | D10: 東泥 | E10: 傳產-水泥 | F10: 水泥營建 | G10: 水泥建材 | I10: 102.4 | L10: 觀光餐飲 | M10: 觀光餐飲 | N10: (1)水泥製造與買賣(2)石灰石之開採及銷售、(3)水泥加工製品及預拌混凝土之製造及銷售、(4)廠房及大樓出租業(5)廢棄物處理業 | R10: 水泥建材
C11: 1201 | D11: 味全 | E11: 傳產-食品 | F11: 消費觀光 | G11: 食品 | I11: 83 | L11: 物流倉儲 | M11: 物流倉儲 | N11: 食品製造及販賣 | R11: 食品
C12: 1203 | D12: 味王 | E12: 傳產-食品 | F12: 消費觀光 | G12: 食品 | I12: 96.7 | L12: 供電與變壓 | M12: 供電與變壓 | N12: 味精醬油罐頭調理速食品飲料等製造及營銷有關進出口業務、洋菸酒類及飲料之進口及經銷、汽車檢驗及修理 | R12: 食品
C13: 1210 | D13: 大成 | E13: 傳產-食品 | F13: 消費觀光 | G13: 食品 | H13: Yes | I13: 569.1 | L13: 電機 | M13: 電機 | N13: 飼料、大宗油脂、肉品 | R13: 食品
C14: 1213 | D14: 大飲 | E14: 傳產-食品 | F14: 消費觀光 | G14: 食品 | I14: 7.2 | L14: 運動健身器材 | M14: 運動健身 器材 | N14: 製造蘋果汽水礦泉水及各種汽水飲料等之批發、經銷各國及國內有關飲料之產品副產品加工產品、百貨批發 | R14: 食品
C15: 1215 | D15: 卜蜂 | E15: 傳產-食品 | F15: 消費觀光 | G15: 食品 | H15: Yes | I15: 377.3 | L15: 工具機與機械元件 | M15: 工具機與 機械元件 | N15: 各種飼料生產加工配製銷售進口及買賣、各種禽畜育種、電動屠宰業務及各種禽畜加工品製品銷售、各種肉類加工品與調理食品及蛋品生產銷售等業務 | R15: 食品
C16: 1216 | D16: 統一 | E16: 傳產-食品 | F16: 消費觀光 | G16: 食品 | H16: Yes | I16: 4772.9 | K16: YES | L16: 鋼鐵金屬 | M16: 鋼鐵金屬 | N16: 食品、便利商店、流通、包裝容器 | R16: 食品
C17: 1217 | D17: 愛之味 | E17: 傳產-食品 | F17: 消費觀光 | G17: 食品 | I17: 51.9 | L17: 汽機車電子 | M17: 汽機車 電子 | N17: 食品 | R17: 食品
C18: 1218 | D18: 泰山 | E18: 傳產-食品 | F18: 消費觀光 | G18: 食品 | I18: 97.8 | L18: 公共工程 | M18: 公共工程 | N18: 各種食用油脂之精製及批發零售各種清涼飲料冷凍調理食品、各種禽畜魚類飼料之加工製造及買賣 | R18: 食品
C19: 1219 | D19: 福壽 | E19: 傳產-食品 | F19: 消費觀光 | G19: 食品 | I19: 49.3 | L19: 半導體設備 | M19: 半導體 設備 | N19: 食用油脂、動物飼料、穀物食品、寵物食品、有機肥料等生產及銷售、進出口國際貿易、大宗穀物進口與銷售 | R19: 食品
C20: 1220 | D20: 台榮 | E20: 傳產-食品 | F20: 消費觀光 | G20: 食品 | I20: 24.7 | L20: 資訊機構件 | M20: 資訊機構件 | N20: 飼料製造販賣、果糖製造販賣、玉米澱粉製造販賣 | R20: 食品
C21: 1225 | D21: 福懋油 | E21: 傳產-食品 | F21: 消費觀光 | G21: 食品 | I21: 69 | L21: 新能源 | M21: 新能源 | N21: 麵粉，飼料，黃豆油，黃豆粉，大麥片，玉米粉之製造與銷售、家畜，家禽之養殖及肉類之加工銷售、一般進口貿易業務(許可業務除外)、 | R21: 食品
C22: 1227 | D22: 佳格 | E22: 傳產-食品 | F22: 消費觀光 | G22: 食品 | H22: Yes | I22: 297.9 | L22: 電線電纜 | M22: 電線電纜 | N22: 嬰兒麥粉，麥片及相關產品之生產製造、食用油及滋養飲料粉之分裝，加工，銷售業務、一般進出口貿易 | R22: 食品
C23: 1229 | D23: 聯華 | E23: 傳產-食品 | F23: 消費觀光 | G23: 食品 | H23: Yes | I23: 792.8 | L23: 傢俱家電 | M23: 傢俱家電 | N23: 麵粉 | R23: 食品
C24: 1231 | D24: 聯華食 | E24: 傳產-食品 | F24: 消費觀光 | G24: 食品 | H24: Yes | I24: 382.5 | L24: LED | M24: LED | N24: 食品 | R24: 食品
C25: 1232 | D25: 大統益 | E25: 傳產-食品 | F25: 消費觀光 | G25: 食品 | I25: 241.6 | L25: 藥品製造 | M25: 藥品製造 | N25: 黃豆油、粉加工，製造及銷售 | R25: 食品
C26: 1233 | D26: 天仁 | E26: 傳產-食品 | F26: 消費觀光 | G26: 食品 | I26: 28.3 | L26: 醫美保健通路 | M26: 醫美保健 通路 | N26: 茶葉製造加工、茶葉製品買賣、茶相關製品 | R26: 食品
C27: 1234 | D27: 黑松 | E27: 傳產-食品 | F27: 消費觀光 | G27: 食品 | I27: 161.6 | L27: 化工 | M27: 化工 | N27: 碳酸飲料，酒類，果蔬汁，咖啡飲料，運動飲料等 | R27: 食品
C28: 1235 | D28: 興泰 | E28: 傳產-食品 | F28: 消費觀光 | G28: 食品 | I28: 106.8 | L28: 醫材 | M28: 醫材 | N28: 飼料 | R28: 食品
C29: 1236 | D29: 宏亞 | E29: 傳產-食品 | F29: 消費觀光 | G29: 食品 | I29: 18.7 | L29: 新藥研發 | M29: 新藥研發 | N29: 糖果、餅乾、巧克力之製造、加工及買賣、月餅、西點、麵包糕餅等食品之製造、加工及買賣、七七巧克力、禮坊名店、 | R29: 食品
C30: 1256 | D30: 鮮活果汁-KY | E30: 傳產-食品 | F30: 消費觀光 | G30: 食品 | I30: 39.9 | L30: 橡膠 | M30: 橡膠 | N30: 果汁、果粒、果粉類等產品之生產與銷售 | R30: 食品
C31: 1301 | D31: 台塑 | E31: 傳產-塑膠 | F31: 塑化橡 | G31: 塑膠 | H31: Yes | I31: 2196.2 | K31: YES | L31: 紙業 | M31: 紙業 | N31: 聚氯乙烯(PVC)、氯乙烯、液(石咸)、聚丙烯、高密度聚乙烯、聚乙烯醋酸乙烯酯、低密度聚乙烯、線性低密度聚乙烯、丙烯酸酯、高吸水性樹脂、碳素纖維、丙烯睛、甲基丙烯酸甲酯及環氧氯丙烷等 | R31: 塑膠
C32: 1303 | D32: 南亞 | E32: 傳產-塑膠 | F32: 塑化橡 | G32: 塑膠 | H32: Yes | I32: 2165.1 | K32: YES | L32: 汽機車製造或代理 | M32: 汽機車製造 或代理 | N32: 各種塑膠加工品、塑膠原料、電子材料、聚酯纖維之製銷、及染整加工、配電盤 | R32: 塑膠
C33: 1304 | D33: 台聚 | E33: 傳產-塑膠 | F33: 塑化橡 | G33: 塑膠 | I33: 109.6 | L33: 散熱 | M33: 散熱 | N33: 塑膠原料之製造、加工及銷售、電子材料、其他 | R33: 塑膠
C34: 1305 | D34: 華夏 | E34: 傳產-塑膠 | F34: 塑化橡 | G34: 塑膠 | I34: 56.5 | L34: IC代工 | M34: IC代工 | N34: 從事生產與銷售塑膠布，塑膠皮，塑膠管，塑膠粒、塑膠粉，鹼氯品及其它有關產品為主要業務 | R34: 塑膠
C35: 1307 | D35: 三芳 | E35: 傳產-塑膠 | F35: 塑化橡 | G35: 塑膠 | I35: 128.3 | L35: 影像與監控 | M35: 影像與 監控 | N35: 聚氨基甲酸加工品之製銷事項不織布起毛布加工品製銷染整事項、聚氯乙烯加工之製銷事項塑膠加工品生產技術研究改良事項、各種皮革加工之製銷事項有關事業之投資經營事項 | R35: 塑膠
C36: 1308 | D36: 亞聚 | E36: 傳產-塑膠 | F36: 塑化橡 | G36: 塑膠 | I36: 66.2 | L36: EMS | M36: EMS | N36: 低密度聚乙烯及乙烯醋酸乙烯酯共聚合樹脂之生產及銷售、高密度聚乙烯及線型低密度聚乙烯之銷售、分解性塑膠原料之製造及銷售 | R36: 塑膠
C37: 1309 | D37: 台達化 | E37: 傳產-塑膠 | F37: 塑化橡 | G37: 塑膠 | I37: 39.7 | L37: PCB製造 | M37: PCB製造 | N37: 聚苯乙烯及加工品之製銷，丙烯(月青)、丁二烯、苯乙烯共聚體樹脂、ABS之製銷，﹝丙烯(月青)、苯乙烯共聚合樹脂﹞SAN之製銷、玻璃棉及其有關產品之製銷，塑膠原料及加工品之製銷 | R37: 塑膠
C38: 1310 | D38: 台苯 | E38: 傳產-塑膠 | F38: 塑化橡 | G38: 塑膠 | I38: 40.2 | L38: 網通 | M38: 網通 | N38: 苯乙烯單體、對二乙苯、甲苯乙苯 | R38: 塑膠
C39: 1312 | D39: 國喬 | E39: 傳產-塑膠 | F39: 塑化橡 | G39: 塑膠 | I39: 102.6 | L39: 電腦週邊 | M39: 資訊週邊 | N39: 石油化工原料製造業、合成樹脂及塑膠製造業、國際貿易業(除許可業務外得經營法令非禁止或限制之業務) | R39: 塑膠
C40: 1313 | D40: 聯成 | E40: 傳產-塑膠 | F40: 塑化橡 | G40: 塑膠 | H40: Yes | I40: 107.1 | L40: 被動元件 | M40: 被動元件 | N40: 有機酸及其衍生物、塑膠增韌劑、樹脂及塑膠原料 | R40: 塑膠
C41: 1314 | D41: 中石化 | E41: 傳產-塑膠 | F41: 塑化橡 | G41: 塑膠 | I41: 250.6 | L41: 連接元件 | M41: 連接元件 | N41: 石油化學產品CPLAN之製造及銷售 | R41: 塑膠
...
